Workbook

Sheet Setup

Sheet Customer Enquiry Form
A1: Timestamp | B1: Name | C1: Mobile Number | D1: Purchase Type | E1: Category | F1: Product | G1: Estimate Budget | H1: Specific Requirement | I1: Design Reference if any upload pic | J1: Attended by | K1: Follow up Needed by | L1: Where Did You Find US | M1: Requirement Needed by Date | N1: Priority Urgency | O1: Referred By (optional) | P1: Email Id | Q1: url
A2: 44625.486 | B2: Kusha ji | D2: General | E2: Diamond Jewellery, Gold Jewellery | F2: Earring / Tops | G2: 20k | H2: Round vaali with plain heart shaped gold hanging | J2: Saarika | K2: Saarika | L2: Old | M2: 44625 | N2: This Week | Q2: https://docs.google.com/forms/d/e/1FAIpQLSeQ0wUAy9WJrwwZ_8x6kCxvJSihLYtbLF2nbMncVH08fybLWQ/viewform?edit2=2_ABaOnucOBtuzIBq648ZrMfcYHOkW9UiP3oPSq_Lj9KHly_tPcKrmgp2EdiB5cOtOKJ0hAaw
A3: 44625.563 | B3: Vinod | D3: General | E3: Diamond Jewellery, Solitaire | F3: Chain, Nosepin | G3: 50000 | J3: Shivani | K3: Seema Mam | L3: Old | M3: 44628 | N3: This Week | Q3: https://docs.google.com/forms/d/e/1FAIpQLSeQ0wUAy9WJrwwZ_8x6kCxvJSihLYtbLF2nbMncVH08fybLWQ/viewform?edit2=2_ABaOnucjSholQ0zznOsx1FWO_yTZ6SDKtCeJJ5kjGajuBRYP2y8S8fehKqvKRlknV7fXnrY
A4: 44626.502 | B4: Jojo | D4: General | E4: Diamond Jewellery | F4: Ladies Bracelet / Kada | G4: 150000 | H4: Cartier | J4: Saurav Sir | K4: Saurav Sir | L4: Old | M4: 44635 | N4: This Month | Q4: https://docs.google.com/forms/d/e/1FAIpQLSeQ0wUAy9WJrwwZ_8x6kCxvJSihLYtbLF2nbMncVH08fybLWQ/viewform?edit2=2_ABaOnudzstLQLbsbfevudiqxmMbvo4c8F070bC6Ec9-XWfWjuyfadq2gpm97VcnByzM_lWg
A5: 44626.505 | B5: Jaspreet ji | D5: General | E5: Gemstone | F5: Misc | G5: 5000 | H5: Strings | J5: Shivani | K5: Shivani | L5: Old | M5: 44635 | N5: Later | Q5: https://docs.google.com/forms/d/e/1FAIpQLSeQ0wUAy9WJrwwZ_8x6kCxvJSihLYtbLF2nbMncVH08fybLWQ/viewform?edit2=2_ABaOnuef_QZ5PJqCr0A29KrVkoIpdtcp6RFnaomNPQxqa9dhkZAJyO8lFtRmuMfh2Yru4fY
A6: 44626.513 | B6: Nayaa | D6: General | E6: Solitaire | F6: Earring / Tops | G6: 800000 | J6: Saurav Sir | K6: Shivani | L6: Old | M6: 44635 | N6: This Month | Q6: https://docs.google.com/forms/d/e/1FAIpQLSeQ0wUAy9WJrwwZ_8x6kCxvJSihLYtbLF2nbMncVH08fybLWQ/viewform?edit2=2_ABaOnudv1eVSFQipyUBIKXWvcu6u4piRqVxPSAeLKoubF7n7aMVzCRm0IPuzhKWCHkLXvKA
A7: 44626.522 | B7: Kamal ji | D7: General | E7: Solitaire | F7: Gents Ring | G7: 100000 | J7: Sanjeev Sir | K7: Shivani | L7: Old | M7: 3/15/0022 | N7: This Month | Q7: https://docs.google.com/forms/d/e/1FAIpQLSeQ0wUAy9WJrwwZ_8x6kCxvJSihLYtbLF2nbMncVH08fybLWQ/viewform?edit2=2_ABaOnudmPtp-Yo7RJhF-TX7kjoSvgyWU41wdPmDThSvksNUM6S-QQGMiBZOiP6FluTV5ZtM
A8: 44626.523 | B8: Aditi ji | D8: General | E8: Gold Jewellery | F8: Chain | G8: 20000 | J8: Shivani | K8: Shivani | L8: Old | M8: 3/10/0022 | N8: This Month | Q8: https://docs.google.com/forms/d/e/1FAIpQLSeQ0wUAy9WJrwwZ_8x6kCxvJSihLYtbLF2nbMncVH08fybLWQ/viewform?edit2=2_ABaOnudCq-EU8GSLgt4-aW5ke8lVNZrfPZ2MVjHS6gbu6xW3APTVvBbmTKhyuTVo2QBWzf4
A9: 44626.526 | B9: Vineeta ji AV | D9: General | E9: Gold Jewellery | F9: Necklace Set | G9: Necklace Set | J9: Sanjeev Sir | K9: Shivani | L9: Old | M9: 3/30/0022 | N9: This Month | Q9: https://docs.google.com/forms/d/e/1FAIpQLSeQ0wUAy9WJrwwZ_8x6kCxvJSihLYtbLF2nbMncVH08fybLWQ/viewform?edit2=2_ABaOnud8T0R4en4Ba9JioWznv4aRt7hUzMQd9p6Lw2O9OW9GThL9t6GXSQiRVroTw_32_XI
A10: 44626.528 | B10: Nidhi ji weblink | D10: General | E10: Gold 24kt | F10: Misc | G10: 1000000 | J10: Shivani | K10: Shivani | L10: Old | M10: 3/30/0022 | N10: This Month | Q10: https://docs.google.com/forms/d/e/1FAIpQLSeQ0wUAy9WJrwwZ_8x6kCxvJSihLYtbLF2nbMncVH08fybLWQ/viewform?edit2=2_ABaOnufqNoSp79APZEidMKtRkuQ_OswUqDzptB_SiQZp02M3nUvbCPK3gCouTdmfqqy4S2g
A11: 44626.666 | B11: Pradeep Sachdeva ji | D11: General | E11: Gold Jewellery | F11: Gents Bracelet / Kada | G11: 250000 | J11: Saurav Sir | K11: Shivani | L11: Old | M11: 3/15/0022 | N11: This Month | Q11: https://docs.google.com/forms/d/e/1FAIpQLSeQ0wUAy9WJrwwZ_8x6kCxvJSihLYtbLF2nbMncVH08fybLWQ/viewform?edit2=2_ABaOnudO6Z8VUv-EFN6OXH8DD9GWjlu0VN93Iw7DGizr7gZGrUnvFNT3Lo8BFOY1y1sCJC8
A12: 44626.668 | B12: Shobha jo c o sheera | D12: General | E12: Diamond Jewellery, Gemstone | F12: Misc | G12: 50000 | J12: Pallavi | K12: Saarika | L12: Reference | M12: 3/15/0022 | N12: This Month | Q12: https://docs.google.com/forms/d/e/1FAIpQLSeQ0wUAy9WJrwwZ_8x6kCxvJSihLYtbLF2nbMncVH08fybLWQ/viewform?edit2=2_ABaOnufka6HO4xJFRWoKBT5oupkTDgJ0_tAP3liJJxf-1Q3aBJxx6CPMar2sL_sOu7sKMZ4
A13: 44626.669 | B13: Sareena ji | D13: Gifting | E13: Silver | F13: Misc | G13: 5000 | J13: Shivani | K13: Shivani | L13: Old | M13: 3/10/0022 | N13: This Week | Q13: https://docs.google.com/forms/d/e/1FAIpQLSeQ0wUAy9WJrwwZ_8x6kCxvJSihLYtbLF2nbMncVH08fybLWQ/viewform?edit2=2_ABaOnuc9erjsOwfkNDVTn8bOLGNIgcEAXBqlUi8-OIOD2_WGMpX_rWK3Bl6iKh_Hp6OSpNQ
A14: 44626.671 | B14: Mridu ji | D14: General | E14: Solitaire | F14: Bangle | G14: 5500000 | H14: .50 pointer bangles GHVS | J14: Shivani | K14: Shivani | L14: Reference | M14: 3/10/0022 | N14: This Week | Q14: https://docs.google.com/forms/d/e/1FAIpQLSeQ0wUAy9WJrwwZ_8x6kCxvJSihLYtbLF2nbMncVH08fybLWQ/viewform?edit2=2_ABaOnue8XevbleIOLV6Zvd2G37FlNxMZJOVw5Q8ZveOXrl-aDLrqeulbaZs0ZmX_O5OIZGA
A15: 44626.673 | B15: Sonali ji | D15: General | E15: Diamond Jewellery, Solitaire | F15: Solitaire | G15: 500000 | J15: Sanjeev Sir | K15: Shivani | L15: Old | M15: 3/10/0022 | N15: This Week | Q15: https://docs.google.com/forms/d/e/1FAIpQLSeQ0wUAy9WJrwwZ_8x6kCxvJSihLYtbLF2nbMncVH08fybLWQ/viewform?edit2=2_ABaOnufU10HXks4gtKyjw2PBrrIZ7bPmtUydfCqliHEmErlsazHoHwp9wwSAXEjdDzzgKt0
A16: 44628.493 | B16: Anuj ji | D16: General | E16: Diamond Jewellery | F16: Nosepin | G16: 100000 | J16: Shivani | K16: Shivani | L16: Old | M16: 3/10/0022 | N16: This Week | Q16: https://docs.google.com/forms/d/e/1FAIpQLSeQ0wUAy9WJrwwZ_8x6kCxvJSihLYtbLF2nbMncVH08fybLWQ/viewform?edit2=2_ABaOnufFH8SnKCuhonbjl2dCGvrCncAaPrAMZz7Cwjz2fpfcF0S4PLFCFSMPjINr9CpOZEA
A17: 44629.479 | B17: Sangeeta ji | D17: Gifting | E17: Silver | F17: Misc | J17: Saurav Sir | K17: Shivani | L17: Old | M17: 3/15/0022 | N17: This Month | Q17: https://docs.google.com/forms/d/e/1FAIpQLSeQ0wUAy9WJrwwZ_8x6kCxvJSihLYtbLF2nbMncVH08fybLWQ/viewform?edit2=2_ABaOnudtBKuQlAKSKmcGaH3jWqaYVTx86soVcJ-EDjo7hh0oWjmZe8C_usSNef6DiKAxzU4
A18: 44635.722 | B18: Sunny Anchal | C18: 9810265393 | D18: General | E18: Solitaire | F18: Solitaire | G18: 1500+ | H18: 4-5ct round range 25-30 | J18: Saurav Sir | K18: Saurav Sir | L18: Old | M18: 44637 | N18: This Month | Q18: https://docs.google.com/forms/d/e/1FAIpQLSeQ0wUAy9WJrwwZ_8x6kCxvJSihLYtbLF2nbMncVH08fybLWQ/viewform?edit2=2_ABaOnuc8H0F6VxAESAEYvHMp1DIAZ4L3BkNgLHEemRz_GT__2UHav6-PTcU8LU7zETkhmDE
A19: 44636.493 | B19: Arun gupta ji | D19: General | E19: Gold Jewellery, Solitaire | F19: Earring / Tops, Necklace Set | J19: Sanjeev Sir | K19: Shivani | L19: Old | M19: 3/15/0022 | N19: This Week | Q19: https://docs.google.com/forms/d/e/1FAIpQLSeQ0wUAy9WJrwwZ_8x6kCxvJSihLYtbLF2nbMncVH08fybLWQ/viewform?edit2=2_ABaOnuc82M0MnGYwWslEVOfcdsN9fr5i2iHOy1Vg5BSzzzZNOBVM6mo5NWyovhjnf581ZaM
A20: 44636.495 | B20: Vijay ji Amritsar | D20: General | E20: Gold Jewellery, Solitaire | F20: Necklace Set, Solitaire | J20: Sanjeev Sir | K20: Shivani | L20: Old | M20: 3/15/0022 | N20: This Week | Q20: https://docs.google.com/forms/d/e/1FAIpQLSeQ0wUAy9WJrwwZ_8x6kCxvJSihLYtbLF2nbMncVH08fybLWQ/viewform?edit2=2_ABaOnudShLJWg3dSuNxIAUAfVQg5mpuRyvp9QszOlmROUYtVrt0Z7XeejNh423tF1nY3m00
A21: 44636.498 | B21: Abhinav gupta | C21: 9711789059 | D21: General | E21: Diamond Jewellery | F21: Ladies Ring | H21: Fancy Big Ring | J21: Pallavi | K21: Shivani | L21: Old | M21: 3/13/0022 | N21: This Month | Q21: https://docs.google.com/forms/d/e/1FAIpQLSeQ0wUAy9WJrwwZ_8x6kCxvJSihLYtbLF2nbMncVH08fybLWQ/viewform?edit2=2_ABaOnueCDtj4VPxWl6VFbbL8jupX5CTCAq3hp2blVV3i0lZqeXRld_dACJd0YwZ0O_XHgf4
A22: 44636.502 | B22: Satish ji | D22: General | E22: Solitaire | F22: Solitaire Ring | H22: 3-4 ct solitaire | J22: Sanjeev Sir | K22: Shivani | L22: Old | M22: 3/15/0022 | N22: This Month | Q22: https://docs.google.com/forms/d/e/1FAIpQLSeQ0wUAy9WJrwwZ_8x6kCxvJSihLYtbLF2nbMncVH08fybLWQ/viewform?edit2=2_ABaOnudMErVkFq2TMTblXUutgWwRnbW51W7MmcFAuNsGDJggHzUzeZ9Q5ozmoHSxWQPghU0
A23: 44636.509 | B23: Rammo didi | D23: Gifting | E23: Silver | F23: Misc | G23: 5 | J23: Shivani | K23: Shivani | L23: Old | M23: 3/15/0022 | N23: This Week | Q23: https://docs.google.com/forms/d/e/1FAIpQLSeQ0wUAy9WJrwwZ_8x6kCxvJSihLYtbLF2nbMncVH08fybLWQ/viewform?edit2=2_ABaOnuc7VksDuY6bH1GiOtJuafk91fHnTLZbNeDer1y5iZE0qMwvKGgQ4FszCpiNUnpVoHU
A24: 44636.526 | B24: Ankur ji CL | D24: Kitty | E24: Kitty | F24: Misc | H24: 3 gram coin | J24: Saurav Sir | K24: Saurav Sir | L24: Old | M24: 3/15/0022 | N24: This Month | Q24: https://docs.google.com/forms/d/e/1FAIpQLSeQ0wUAy9WJrwwZ_8x6kCxvJSihLYtbLF2nbMncVH08fybLWQ/viewform?edit2=2_ABaOnueWqpAzFDX08CmCtPz3UajMCKOmKXkhTjvwT3fcj2mSr9Y7m4qgbEbKX8BAbngJjP0
A25: 44643.688 | B25: Khurana ji | D25: General | E25: Silver | F25: Necklace Set | J25: Saurav Sir | K25: Shivani | L25: Old | M25: 44651 | N25: This Month | Q25: https://docs.google.com/forms/d/e/1FAIpQLSeQ0wUAy9WJrwwZ_8x6kCxvJSihLYtbLF2nbMncVH08fybLWQ/viewform?edit2=2_ABaOnudqXjPiMidtiEFJ2dxQmsyOqCe9dLKDPDG-8gAPGNrtdRDmHbhY2kuwMmAfQma295Y
A26: 44643.69 | B26: Ritin ji | C26: 9829452525 | D26: General | E26: Solitaire | F26: Earring / Tops | H26: 1.00 ct | J26: Saurav Sir | K26: Shivani | L26: Old | M26: 44651 | N26: This Month | Q26: https://docs.google.com/forms/d/e/1FAIpQLSeQ0wUAy9WJrwwZ_8x6kCxvJSihLYtbLF2nbMncVH08fybLWQ/viewform?edit2=2_ABaOnudEjLWPj55sqw4qj9MSo0oSnsDAfSbr1FcOeLcek3NuRs97QRYY6fbUBT7Jx-e-MGk
A27: 44643.691 | B27: Gaurav ji | C27: 9111000111 | D27: General | E27: Gold Jewellery | F27: Bangle | J27: Saurav Sir | K27: Shivani | L27: Old | M27: 44651 | N27: This Month | Q27: https://docs.google.com/forms/d/e/1FAIpQLSeQ0wUAy9WJrwwZ_8x6kCxvJSihLYtbLF2nbMncVH08fybLWQ/viewform?edit2=2_ABaOnucoHthyvcR-P3HYtzl92jA-jLbUZQqHK-ItmgYLgblqCxKraEibhLfhj-a-YylMIyA
A28: 44643.692 | B28: Sonal ji | D28: General | E28: Polki | F28: Earring / Tops | J28: Saurav Sir | K28: Saarika | L28: Old | M28: 44651 | N28: This Month | Q28: https://docs.google.com/forms/d/e/1FAIpQLSeQ0wUAy9WJrwwZ_8x6kCxvJSihLYtbLF2nbMncVH08fybLWQ/viewform?edit2=2_ABaOnudr1wd2Oy_UwcNNtmZR39C_gvOynHV247G7KDhHidbM4KpshSiXAvZ5YV4AH7tRKD0
A29: 44643.693 | B29: Pradeep sachdeva ji | D29: General | E29: Gold Jewellery | F29: Bangle | G29: 1500+ | J29: Saurav Sir | K29: Shivani | L29: Old | M29: 44651 | N29: This Month | Q29: https://docs.google.com/forms/d/e/1FAIpQLSeQ0wUAy9WJrwwZ_8x6kCxvJSihLYtbLF2nbMncVH08fybLWQ/viewform?edit2=2_ABaOnucxMsYOIH4YXb0eCm2m7AsZ9eKd41wIuk-Q2xGOzjR5TxCBvtsErQgr1cRJGe1k2yQ
A30: 44645.583 | B30: Lalit Mehra | D30: General | E30: Gemstone | F30: Gemstone | H30: 3 ratti | J30: Sanjeev Sir | K30: Shivani | L30: Old | M30: 44651 | N30: This Month | Q30: https://docs.google.com/forms/d/e/1FAIpQLSeQ0wUAy9WJrwwZ_8x6kCxvJSihLYtbLF2nbMncVH08fybLWQ/viewform?edit2=2_ABaOnucnIl29Yt-KjOVJx1Zm8F4FQelnGgAaQmiA7aFQwOQXJoXyQKYSi614TFclx-3DQNU
A31: 44645.802 | B31: Shashi ji jaipur | C31: 9828158871 | D31: General | E31: Diamond Jewellery | F31: Chain, Necklace Set, Ladies Ring, Solitaire | G31: 750-1000 | J31: Saurav Sir | K31: Saarika | L31: Old | M31: 44645 | N31: This Week | Q31: https://docs.google.com/forms/d/e/1FAIpQLSeQ0wUAy9WJrwwZ_8x6kCxvJSihLYtbLF2nbMncVH08fybLWQ/viewform?edit2=2_ABaOnueNYsSlY2wMog1-GG65HFhU5AMIwkg5Hp4TC-v9PmSt1zQlOVPqOSNXp2Mf_sMQQvs
A32: 44678.492 | B32: Puneet jain | D32: Gifting | E32: Solitaire | F32: Solitaire | G32: 750-1000 | J32: Sanjeev Sir | K32: Shivani | L32: Reference | M32: 4/30/0022 | N32: This Month | Q32: https://docs.google.com/forms/d/e/1FAIpQLSeQ0wUAy9WJrwwZ_8x6kCxvJSihLYtbLF2nbMncVH08fybLWQ/viewform?edit2=2_ABaOnucI-EYKA4fkV_WpDA26gRHrI7jMBrinenkiDutZRc7MMU86r6-PynxqsR-IgKmKJrM
A33: 44678.493 | B33: Chattarpati ji | D33: General | E33: Gold Jewellery | F33: Bangle | J33: Sanjeev Sir | K33: Shivani | L33: Old | M33: 5/5/0022 | N33: This Month | Q33: https://docs.google.com/forms/d/e/1FAIpQLSeQ0wUAy9WJrwwZ_8x6kCxvJSihLYtbLF2nbMncVH08fybLWQ/viewform?edit2=2_ABaOnufdiLKHlsa4JX-pIMDN1cUruT4CFzoXu6IcRkTEAwgErnCkdJVWHCpQVglgdwnWdqk
A34: 44680.736 | B34: Shashikant ji | D34: General | E34: Diamond Jewellery, Solitaire | F34: Bangle, Solitaire | H34: FG VVS 17 pointer bangles And 1.60 + 1.60 each pc | J34: Saurav Sir | K34: Shivani | L34: Old | M34: 5/10/0022 | N34: This Month | Q34: https://docs.google.com/forms/d/e/1FAIpQLSeQ0wUAy9WJrwwZ_8x6kCxvJSihLYtbLF2nbMncVH08fybLWQ/viewform?edit2=2_ABaOnueEqk26LvFXb6hmACEYOGriy4YIWhJ3FO5zKzaWHv_izLdISNo-vWo9vi198828nbY
A35: 44680.738 | B35: Suchita ji | D35: General | E35: Diamond Jewellery, Gold Jewellery | F35: Earring / Tops | G35: 30-50 | J35: Shivani | K35: Shivani | L35: Old | M35: 5/5/0022 | N35: This Month | Q35: https://docs.google.com/forms/d/e/1FAIpQLSeQ0wUAy9WJrwwZ_8x6kCxvJSihLYtbLF2nbMncVH08fybLWQ/viewform?edit2=2_ABaOnuesfEGKeT2XLhNiIoCYgDbDHzygpNLvIKW1W8OEO-vpRD7L5gNUw7GuhDUiLSLYWUU
A36: 44680.739 | B36: Faridabad | D36: General | E36: Solitaire | F36: Bangle, Solitaire | H36: 10 ct pair and 7. 00 ct pc and 1.50 ct bangle | J36: Saurav Sir | K36: Saurav Sir | L36: Old | M36: 5/10/0022 | N36: This Month | Q36: https://docs.google.com/forms/d/e/1FAIpQLSeQ0wUAy9WJrwwZ_8x6kCxvJSihLYtbLF2nbMncVH08fybLWQ/viewform?edit2=2_ABaOnudDN-904Ec89OvdxY3kSI87iEcQB98sK4nGQ7MNv6WyVpxl2QNhilDeWHRG8hbwcHw
A37: 44681.558 | B37: Charu Ji | D37: Gifting | E37: Gold Jewellery | F37: Chain | G37: 30-50 | J37: Shivani | K37: Shivani | L37: Old | M37: 5/15/0022 | N37: This Month | Q37: https://docs.google.com/forms/d/e/1FAIpQLSeQ0wUAy9WJrwwZ_8x6kCxvJSihLYtbLF2nbMncVH08fybLWQ/viewform?edit2=2_ABaOnucrVgOYsiSTSx3QKmTsfSlXb-fIGGM7gWltOnyoYZ332XD_ozejrBIyFnYpU5AsQx8
A38: 44684.611 | B38: Sabina ji | D38: General | E38: Gold Jewellery | F38: Bangle | H38: Kundan bangle | J38: Saurav Sir | K38: Shivani | L38: Old | M38: 5/15/0022 | N38: This Month | Q38: https://docs.google.com/forms/d/e/1FAIpQLSeQ0wUAy9WJrwwZ_8x6kCxvJSihLYtbLF2nbMncVH08fybLWQ/viewform?edit2=2_ABaOnudkRctbvTuUNJzXs0QGFXMQiWq1TLuloQig-dzlKWx73qcvb_R37rW4HH4jHHdeOYk
A39: 44685.489 | B39: Sabina ji | D39: General | E39: Gold Jewellery, Solitaire | F39: Bangle, Solitaire | J39: Saurav Sir | K39: Saurav Sir | L39: Old | M39: 5/15/0022 | N39: This Month | Q39: https://docs.google.com/forms/d/e/1FAIpQLSeQ0wUAy9WJrwwZ_8x6kCxvJSihLYtbLF2nbMncVH08fybLWQ/viewform?edit2=2_ABaOnufp7FhY8NkWnbkd_YNcp4jE4izzEWlRMgkST4rUtdsYEQTJU1-rL2KQ9DOLct82E9k
A40: 44689.484 | B40: Anju Malik | D40: General | E40: Gold Jewellery | F40: Pendant Set | H40: 30-35 gms | J40: Radhu Mam | K40: Radhu Mam | L40: Old | M40: 5/15/0022 | N40: This Month | Q40: https://docs.google.com/forms/d/e/1FAIpQLSeQ0wUAy9WJrwwZ_8x6kCxvJSihLYtbLF2nbMncVH08fybLWQ/viewform?edit2=2_ABaOnucdwO_2WInpvPXQNqDyDTU2UV2av_Pz3BJlb-vXog78ecyx-dV1zmvOTmNSCcNyyDE
...

Sheet Sheet13
A2: 45262 | B2: Shama Kapoor | C2: 919555586195 | J2: Bhumika | P2: shamakapoor1975@gmail.com
A3: 45262 | B3: Ritesh Saini | C3: 919896859990 | J3: Bhumika | P3: sainiritesh099@gmail.com
A4: 45262 | B4: Bharat kochhar | C4: 918146302837 | J4: Bhumika | P4: bharatkochhar777@gmail.com
A5: 45262 | B5: Cuboid Jeans Co | C5: 919999995592 | J5: Bhumika | P5: cuboidjeansco@gmail.com
A6: 45262 | B6: Kiru Bisht | C6: 919711192649 | J6: Bhumika | P6: kiranbisht109@yahoo.com
A7: 45262 | B7: Vijay Bansal | C7: 919718028256 | J7: Bhumika | P7: vijaykumarbansal30@gmail.com
A8: 45262 | B8: Sushma Dhar | C8: 919717462277 | J8: Bhumika | P8: drsushmadhar@yahoo.com
A9: 45262 | B9: Indu Chaudhary | C9: 919599427401 | J9: Bhumika | P9: indukumari3@gmail.com
A10: 45262 | B10: Lovely Santosh Sk | C10: 918448745003 | J10: Bhumika | P10: santoshbosak18@gmail.com
A11: 45262 | B11: Bina Pathak | C11: 919548916659 | J11: Bhumika | P11: bina.pathak2019@gmail.com
A12: 45262 | B12: Jeeti Bhinder | C12: 919996145792 | J12: Bhumika | P12: 676712@gmail.com
A13: 45262 | B13: Vung Biaklun | C13: 919650585014 | J13: Bhumika | P13: luwang334@gmail.com
... A45: 45262 | B45: Gauraev Mittal | C45: 919911198444 | J45: Bhumika | P45: dpconstco786@gmail.com
A46: 45314 | B46: Asha Solanki | C46: =+918800141965 -> 918800141965 | F46: Wedding jewellery | P46: ashasolanki098@gmail.com
A47: 45314 | B47: Noor Afroz | C47: =+919971016813 -> 919971016813 | F47: Wedding jewellery | P47: noorafroz85@gmail.com
A48: 45314 | B48: Kalp Jyoti Jain | C48: =+919871276271 -> 919871276271 | F48: Wedding jewellery | P48: Kalpjyotijain@gmail.com
A49: 45314 | B49: Simmi Mishra | C49: =+919870255623 -> 919870255623 | F49: Wedding jewellery | P49: simmimishra1967@gmail.com
A50: 45314 | B50: Archana Prajapati | C50: =+919559725020 -> 919559725020 | F50: Wedding jewellery | P50: efmyuvi@gmail.com
A51: 45314 | B51: Meena Gupta | C51: =+919582908403 -> 919582908403 | F51: Wedding jewellery | P51: meenagupta.1111972@gmail.com
A52: 45314 | B52: Manisha Goel | C52: =+918800374621 -> 918800374621 | F52: Wedding jewellery | P52: manishagoelmg123@gmail.com
A53: 45314 | B53: Seema Narula | C53: =+919910056771 -> 919910056771 | F53: Wedding jewellery | P53: shailendernarula56@gmail.com

Sheet FMS
A1: =now() -> 46133.984
A2: what | O2: Enquire & Coordinate with client | U2: Estimate | AB2: Follow up | AI2: Contact for any order update | AN2: Price Negotiation | AS2: Closure Finale | AX2: Reason for Pending
A3: Who | G3: pallavi | K3: pallavi | O3: sales person - first shivani | U3: shivani | AB3: Kajal | AI3: Kajal | AN3: Kajal
A4: How
A5: When | G5: 0.70833333 | K5: 0.79166667 | O5: 1 | U5: 1 | AI5: 0.75 | AN5: 1 | AS5: 2
A6: Timestamp | G6: Planned | H6: Actual | I6: Status | J6: Time Delay | K6: Planned | L6: Actual | M6: Status | N6: Time Delay | O6: Planned | P6: Actual | Q6: Status | R6: Time Delay | S6: Remarks | T6: Share Design with Client | U6: Planned | V6: Actual | W6: Status | X6: Time Delay | Y6: Vendor 1 | Z6: Vendor 2 | AA6: Remarks | AB6: 1 | AC6: 2 | AD6: 3 | AE6: 4 | AF6: 5 | AG6: Remarks | AH6: Planned | AI6: Planned | AJ6: Actual | AK6: Status | AL6: Time Delay | AM6: Remarks | AN6: Planned | AO6: Actual | AP6: Status | AQ6: Time Delay | AR6: Remarks | AS6: Planned | AT6: Actual | AU6: Status | AV6: Time Delay | AW6: Remarks | AX6: Status
A7: {=INDEX('Customer Enquiry Form'!$A$2:$A1000,0)} -> 44625.486 | G7: =if(A7,_xlfn.workday.intl(int(A7),1,"1000000",Holidays!A:A)+17/24,"") -> 44626.708 | H7: =if(H7,H7,if(I7<>"",$A$1,"")) | J7: =if(G7,if(H7<>"",if(H7>G7,H7-G7,""),$A$1-G7),"") -> 1507.2756 | K7: =if(G7,_xlfn.workday.intl(int(G7),0,"1000000",Holidays!A:A)+19/24,"") -> 44626.792 | L7: =if(L7,L7,if(M7<>"",$A$1,"")) | N7: =if(K7,if(L7<>"",if(L7>K7,L7-K7,""),$A$1-K7),"") -> 1507.1922 | O7: =if(A7,_xlfn.WORKDAY.INTL(A7,O$5,"1000000",Holidays!A:A)+hour(A7)/24+MINUTE(A7)/1440,"") -> 44626.485 | P7: 44827.718 | Q7: done | R7: =if(O7,if(P7<>"",if(P7>O7,P7-O7,""),$A$1-O7),"") -> 201.2323 | T7: done | U7: =if(O7,_xlfn.WORKDAY.INTL(O7,U$5,"1000000",Holidays!A:A)+hour(O7)/24+MINUTE(O7)/1440,"") -> 44628.485 | V7: =if(V7,V7,if(W7<>"",$A$1,"")) -> 44916.733 | W7: done | X7: =if(U7,if(V7<>"",if(V7>U7,V7-U7,""),$A$1-U7),"") -> 288.24728 | Y7: done | AB7: 1 | AH7: =(IF(P7="","",P7+AB7+AC7+AD7+AE7+AF7)) -> 44828.718 | AI7: =if(AH7,_xlfn.workday.intl(int(AH7),0,"1000000",Holidays!A:A)+18/24,"") -> 44828.75 | AJ7: =if(AJ7,AJ7,if(AK7<>"",$A$1,"")) -> 44728.715 | AK7: Done | AL7: =if(AI7,if(AJ7<>"",if(AJ7>AI7,AJ7-AI7,""),$A$1-AI7),"") | AN7: =if(AJ7,if(and(hour(AJ7+AN$5)>11,(hour(AJ7+AN$5)<20)),AJ7+AN$5,_xlfn.workday.intl(int(AJ7),1,"1000000",Holidays!A:A)+hour(AJ7+AN$5-$B$1)/24+minute(AJ7)/1440),"") -> 44729.715 | AO7: =if(AO7,AO7,if(AP7<>"",$A$1,"")) -> 44916.733 | AP7: done | AQ7: =if(AN7,if(AO7<>"",if(AO7>AN7,AO7-AN7,""),$A$1-AN7),"") -> 187.01797 | AS7: =if(AJ7,if(and(hour(AJ7+AS$5)>11,(hour(AJ7+AS$5)<20)),AJ7+AS$5,_xlfn.workday.intl(int(AJ7),1,"1000000",Holidays!A:A)+hour(AJ7+AS$5-$B$1)/24+minute(AJ7)/1440),"") -> 44730.715 | AT7: =if(AT7,AT7,if(AU7<>"",$A$1,"")) -> 44730.599 | AU7: yes | AV7: =if(AS7,if(AT7<>"",if(AT7>AS7,AT7-AS7,""),$A$1-AS7),"") | AX7: done
A8: 44625.563 | G8: =if(A8,_xlfn.workday.intl(int(A8),1,"1000000",Holidays!A:A)+17/24,"") -> 44626.708 | H8: =if(H8,H8,if(I8<>"",$A$1,"")) | J8: =if(G8,if(H8<>"",if(H8>G8,H8-G8,""),$A$1-G8),"") -> 1507.2756 | K8: =if(G8,_xlfn.workday.intl(int(G8),0,"1000000",Holidays!A:A)+19/24,"") -> 44626.792 | L8: =if(L8,L8,if(M8<>"",$A$1,"")) | N8: =if(K8,if(L8<>"",if(L8>K8,L8-K8,""),$A$1-K8),"") -> 1507.1922 | O8: =if(A8,_xlfn.WORKDAY.INTL(A8,O$5,"1000000",Holidays!A:A)+hour(A8)/24+MINUTE(A8)/1440,"") -> 44626.562 | P8: 44728.721 | Q8: Done | R8: =if(O8,if(P8<>"",if(P8>O8,P8-O8,""),$A$1-O8),"") -> 102.15859 | U8: =if(O8,_xlfn.WORKDAY.INTL(O8,U$5,"1000000",Holidays!A:A)+hour(O8)/24+MINUTE(O8)/1440,"") -> 44628.562 | V8: =if(V8,V8,if(W8<>"",$A$1,"")) | X8: =if(U8,if(V8<>"",if(V8>U8,V8-U8,""),$A$1-U8),"") -> 1505.4214 | AH8: =IF(P8="","",P8+AB8+AC8+AD8+AE8+AF8) -> 44728.721 | AI8: =if(AH8,_xlfn.workday.intl(int(AH8),0,"1000000",Holidays!A:A)+18/24,"") -> 44728.75 | AJ8: =if(AJ8,AJ8,if(AK8<>"",$A$1,"")) -> 44728.717 | AK8: Done | AL8: =if(AI8,if(AJ8<>"",if(AJ8>AI8,AJ8-AI8,""),$A$1-AI8),"") | AN8: =if(AJ8,if(and(hour(AJ8+AN$5)>11,(hour(AJ8+AN$5)<20)),AJ8+AN$5,_xlfn.workday.intl(int(AJ8),1,"1000000",Holidays!A:A)+hour(AJ8+AN$5-$B$1)/24+minute(AJ8)/1440),"") -> 44729.717 | AO8: =if(AO8,AO8,if(AP8<>"",$A$1,"")) | AQ8: =if(AN8,if(AO8<>"",if(AO8>AN8,AO8-AN8,""),$A$1-AN8),"") -> 1404.2674 | AS8: =if(AJ8,if(and(hour(AJ8+AS$5)>11,(hour(AJ8+AS$5)<20)),AJ8+AS$5,_xlfn.workday.intl(int(AJ8),1,"1000000",Holidays!A:A)+hour(AJ8+AS$5-$B$1)/24+minute(AJ8)/1440),"") -> 44730.717 | AT8: =if(AT8,AT8,if(AU8<>"",$A$1,"")) -> 44734.719 | AU8: no | AV8: =if(AS8,if(AT8<>"",if(AT8>AS8,AT8-AS8,""),$A$1-AS8),"") -> 4.0028988 | AX8: Hold
A9: 44626.502 | G9: =if(A9,_xlfn.workday.intl(int(A9),1,"1000000",Holidays!A:A)+17/24,"") -> 44628.708 | H9: =if(H9,H9,if(I9<>"",$A$1,"")) | J9: =if(G9,if(H9<>"",if(H9>G9,H9-G9,""),$A$1-G9),"") -> 1505.2756 | K9: =if(G9,_xlfn.workday.intl(int(G9),0,"1000000",Holidays!A:A)+19/24,"") -> 44628.792 | L9: =if(L9,L9,if(M9<>"",$A$1,"")) | N9: =if(K9,if(L9<>"",if(L9>K9,L9-K9,""),$A$1-K9),"") -> 1505.1922 | O9: =if(A9,_xlfn.WORKDAY.INTL(A9,O$5,"1000000",Holidays!A:A)+hour(A9)/24+MINUTE(A9)/1440,"") -> 44628.502 | R9: =if(O9,if(P9<>"",if(P9>O9,P9-O9,""),$A$1-O9),"") -> 1505.4818 | U9: =if(O9,_xlfn.WORKDAY.INTL(O9,U$5,"1000000",Holidays!A:A)+hour(O9)/24+MINUTE(O9)/1440,"") -> 44629.502 | V9: =if(V9,V9,if(W9<>"",$A$1,"")) | X9: =if(U9,if(V9<>"",if(V9>U9,V9-U9,""),$A$1-U9),"") -> 1504.4818 | AH9: =IF(P9="","",P9+AB9+AC9+AD9+AE9+AF9) | AI9: =if(AH9,_xlfn.workday.intl(int(AH9),0,"1000000",Holidays!A:A)+18/24,"") | AJ9: =if(AJ9,AJ9,if(AK9<>"",$A$1,"")) | AL9: =if(AI9,if(AJ9<>"",if(AJ9>AI9,AJ9-AI9,""),$A$1-AI9),"") | AN9: =if(AJ9,if(and(hour(AJ9+AN$5)>11,(hour(AJ9+AN$5)<20)),AJ9+AN$5,_xlfn.workday.intl(int(AJ9),1,"1000000",Holidays!A:A)+hour(AJ9+AN$5-$B$1)/24+minute(AJ9)/1440),"") | AO9: =if(AO9,AO9,if(AP9<>"",$A$1,"")) | AQ9: =if(AN9,if(AO9<>"",if(AO9>AN9,AO9-AN9,""),$A$1-AN9),"") | AS9: =if(AJ9,if(and(hour(AJ9+AS$5)>11,(hour(AJ9+AS$5)<20)),AJ9+AS$5,_xlfn.workday.intl(int(AJ9),1,"1000000",Holidays!A:A)+hour(AJ9+AS$5-$B$1)/24+minute(AJ9)/1440),"") | AT9: =if(AT9,AT9,if(AU9<>"",$A$1,"")) -> 44734.728 | AU9: no | AV9: =if(AS9,if(AT9<>"",if(AT9>AS9,AT9-AS9,""),$A$1-AS9),"") | AX9: Hold
A10: 44626.505 | G10: =if(A10,_xlfn.workday.intl(int(A10),1,"1000000",Holidays!A:A)+17/24,"") -> 44628.708 | H10: =if(H10,H10,if(I10<>"",$A$1,"")) -> 44744.459 | I10: done | J10: =if(G10,if(H10<>"",if(H10>G10,H10-G10,""),$A$1-G10),"") -> 115.75098 | K10: =if(G10,_xlfn.workday.intl(int(G10),0,"1000000",Holidays!A:A)+19/24,"") -> 44628.792 | L10: =if(L10,L10,if(M10<>"",$A$1,"")) -> 44744.459 | M10: done | N10: =if(K10,if(L10<>"",if(L10>K10,L10-K10,""),$A$1-K10),"") -> 115.66768 | O10: =if(A10,_xlfn.WORKDAY.INTL(A10,O$5,"1000000",Holidays!A:A)+hour(A10)/24+MINUTE(A10)/1440,"") -> 44628.504 | P10: 44744.459 | Q10: done | R10: =if(O10,if(P10<>"",if(P10>O10,P10-O10,""),$A$1-O10),"") -> 115.95521 | T10: done | U10: =if(O10,_xlfn.WORKDAY.INTL(O10,U$5,"1000000",Holidays!A:A)+hour(O10)/24+MINUTE(O10)/1440,"") -> 44629.504 | V10: =if(V10,V10,if(W10<>"",$A$1,"")) -> 44916.733 | W10: done | X10: =if(U10,if(V10<>"",if(V10>U10,V10-U10,""),$A$1-U10),"") -> 287.22899 | Y10: done | AB10: 1 | AC10: 2 | AD10: 3 | AE10: 4 | AF10: 5 | AH10: =IF(P10="","",P10+AB10+AC10+AD10+AE10+AF10) -> 44759.459 | AI10: =if(AH10,_xlfn.workday.intl(int(AH10),0,"1000000",Holidays!A:A)+18/24,"") -> 44759.75 | AJ10: =if(AJ10,AJ10,if(AK10<>"",$A$1,"")) -> 44733.663 | AK10: done | AL10: =if(AI10,if(AJ10<>"",if(AJ10>AI10,AJ10-AI10,""),$A$1-AI10),"") | AN10: =if(AJ10,if(and(hour(AJ10+AN$5)>11,(hour(AJ10+AN$5)<20)),AJ10+AN$5,_xlfn.workday.intl(int(AJ10),1,"1000000",Holidays!A:A)+hour(AJ10+AN$5-$B$1)/24+minute(AJ10)/1440),"") -> 44734.663 | AO10: =if(AO10,AO10,if(AP10<>"",$A$1,"")) -> 44744.459 | AP10: done | AQ10: =if(AN10,if(AO10<>"",if(AO10>AN10,AO10-AN10,""),$A$1-AN10),"") -> 9.7965623 | AS10: =if(AJ10,if(and(hour(AJ10+AS$5)>11,(hour(AJ10+AS$5)<20)),AJ10+AS$5,_xlfn.workday.intl(int(AJ10),1,"1000000",Holidays!A:A)+hour(AJ10+AS$5-$B$1)/24+minute(AJ10)/1440),"") -> 44735.663 | AT10: =if(AT10,AT10,if(AU10<>"",$A$1,"")) -> 44734.728 | AU10: yes | AV10: =if(AS10,if(AT10<>"",if(AT10>AS10,AT10-AS10,""),$A$1-AS10),"") | AX10: done
A11: 44626.513 | G11: =if(A11,_xlfn.workday.intl(int(A11),1,"1000000",Holidays!A:A)+17/24,"") -> 44628.708 | H11: =if(H11,H11,if(I11<>"",$A$1,"")) | J11: =if(G11,if(H11<>"",if(H11>G11,H11-G11,""),$A$1-G11),"") -> 1505.2756 | K11: =if(G11,_xlfn.workday.intl(int(G11),0,"1000000",Holidays!A:A)+19/24,"") -> 44628.792 | L11: =if(L11,L11,if(M11<>"",$A$1,"")) | N11: =if(K11,if(L11<>"",if(L11>K11,L11-K11,""),$A$1-K11),"") -> 1505.1922 | O11: =if(A11,_xlfn.WORKDAY.INTL(A11,O$5,"1000000",Holidays!A:A)+hour(A11)/24+MINUTE(A11)/1440,"") -> 44628.513 | P11: 44912.681 | Q11: done | R11: =if(O11,if(P11<>"",if(P11>O11,P11-O11,""),$A$1-O11),"") -> 284.16773 | T11: done | U11: =if(O11,_xlfn.WORKDAY.INTL(O11,U$5,"1000000",Holidays!A:A)+hour(O11)/24+MINUTE(O11)/1440,"") -> 44629.513 | V11: =if(V11,V11,if(W11<>"",$A$1,"")) -> 44924.794 | W11: done | X11: =if(U11,if(V11<>"",if(V11>U11,V11-U11,""),$A$1-U11),"") -> 295.28061 | Y11: done | AB11: 1 | AC11: 2 | AD11: 3 | AH11: =IF(P11="","",P11+AB11+AC11+AD11+AE11+AF11) -> 44918.681 | AI11: =if(AH11,_xlfn.workday.intl(int(AH11),0,"1000000",Holidays!A:A)+18/24,"") -> 44918.75 | AJ11: =if(AJ11,AJ11,if(AK11<>"",$A$1,"")) | AL11: =if(AI11,if(AJ11<>"",if(AJ11>AI11,AJ11-AI11,""),$A$1-AI11),"") -> 1215.2339 | AN11: =if(AJ11,if(and(hour(AJ11+AN$5)>11,(hour(AJ11+AN$5)<20)),AJ11+AN$5,_xlfn.workday.intl(int(AJ11),1,"1000000",Holidays!A:A)+hour(AJ11+AN$5-$B$1)/24+minute(AJ11)/1440),"") | AO11: =if(AO11,AO11,if(AP11<>"",$A$1,"")) | AQ11: =if(AN11,if(AO11<>"",if(AO11>AN11,AO11-AN11,""),$A$1-AN11),"") | AS11: =if(AJ11,if(and(hour(AJ11+AS$5)>11,(hour(AJ11+AS$5)<20)),AJ11+AS$5,_xlfn.workday.intl(int(AJ11),1,"1000000",Holidays!A:A)+hour(AJ11+AS$5-$B$1)/24+minute(AJ11)/1440),"") | AT11: =if(AT11,AT11,if(AU11<>"",$A$1,"")) -> 44736.55 | AU11: yes | AV11: =if(AS11,if(AT11<>"",if(AT11>AS11,AT11-AS11,""),$A$1-AS11),"") | AX11: done
A12: 44626.522 | G12: =if(A12,_xlfn.workday.intl(int(A12),1,"1000000",Holidays!A:A)+17/24,"") -> 44628.708 | H12: =if(H12,H12,if(I12<>"",$A$1,"")) -> 44744.459 | I12: done | J12: =if(G12,if(H12<>"",if(H12>G12,H12-G12,""),$A$1-G12),"") -> 115.75039 | K12: =if(G12,_xlfn.workday.intl(int(G12),0,"1000000",Holidays!A:A)+19/24,"") -> 44628.792 | L12: =if(L12,L12,if(M12<>"",$A$1,"")) -> 44744.459 | M12: done | N12: =if(K12,if(L12<>"",if(L12>K12,L12-K12,""),$A$1-K12),"") -> 115.66708 | O12: =if(A12,_xlfn.WORKDAY.INTL(A12,O$5,"1000000",Holidays!A:A)+hour(A12)/24+MINUTE(A12)/1440,"") -> 44628.522 | P12: 44744.459 | Q12: done | R12: =if(O12,if(P12<>"",if(P12>O12,P12-O12,""),$A$1-O12),"") -> 115.93657 | T12: done | U12: =if(O12,_xlfn.WORKDAY.INTL(O12,U$5,"1000000",Holidays!A:A)+hour(O12)/24+MINUTE(O12)/1440,"") -> 44629.522 | V12: =if(V12,V12,if(W12<>"",$A$1,"")) -> 44924.794 | W12: done | X12: =if(U12,if(V12<>"",if(V12>U12,V12-U12,""),$A$1-U12),"") -> 295.2716 | Y12: done | AB12: 1 | AC12: 2 | AD12: 3 | AH12: =IF(P12="","",P12+AB12+AC12+AD12+AE12+AF12) -> 44750.459 | AI12: =if(AH12,_xlfn.workday.intl(int(AH12),0,"1000000",Holidays!A:A)+18/24,"") -> 44750.75 | AJ12: =if(AJ12,AJ12,if(AK12<>"",$A$1,"")) -> 44733.663 | AK12: done | AL12: =if(AI12,if(AJ12<>"",if(AJ12>AI12,AJ12-AI12,""),$A$1-AI12),"") | AN12: =if(AJ12,if(and(hour(AJ12+AN$5)>11,(hour(AJ12+AN$5)<20)),AJ12+AN$5,_xlfn.workday.intl(int(AJ12),1,"1000000",Holidays!A:A)+hour(AJ12+AN$5-$B$1)/24+minute(AJ12)/1440),"") -> 44734.663 | AO12: =if(AO12,AO12,if(AP12<>"",$A$1,"")) -> 44744.459 | AP12: done | AQ12: =if(AN12,if(AO12<>"",if(AO12>AN12,AO12-AN12,""),$A$1-AN12),"") -> 9.795894 | AS12: =if(AJ12,if(and(hour(AJ12+AS$5)>11,(hour(AJ12+AS$5)<20)),AJ12+AS$5,_xlfn.workday.intl(int(AJ12),1,"1000000",Holidays!A:A)+hour(AJ12+AS$5-$B$1)/24+minute(AJ12)/1440),"") -> 44735.663 | AT12: =if(AT12,AT12,if(AU12<>"",$A$1,"")) -> 44744.459 | AU12: yes | AV12: =if(AS12,if(AT12<>"",if(AT12>AS12,AT12-AS12,""),$A$1-AS12),"") -> 8.7959279 | AX12: done
A13: 44626.523 | G13: =if(A13,_xlfn.workday.intl(int(A13),1,"1000000",Holidays!A:A)+17/24,"") -> 44628.708 | H13: =if(H13,H13,if(I13<>"",$A$1,"")) -> 44744.458 | I13: done | J13: =if(G13,if(H13<>"",if(H13>G13,H13-G13,""),$A$1-G13),"") -> 115.75012 | K13: =if(G13,_xlfn.workday.intl(int(G13),0,"1000000",Holidays!A:A)+19/24,"") -> 44628.792 | L13: =if(L13,L13,if(M13<>"",$A$1,"")) -> 44744.458 | M13: done | N13: =if(K13,if(L13<>"",if(L13>K13,L13-K13,""),$A$1-K13),"") -> 115.66681 | O13: =if(A13,_xlfn.WORKDAY.INTL(A13,O$5,"1000000",Holidays!A:A)+hour(A13)/24+MINUTE(A13)/1440,"") -> 44628.523 | P13: 44744.459 | Q13: done | R13: =if(O13,if(P13<>"",if(P13>O13,P13-O13,""),$A$1-O13),"") -> 115.93562 | T13: done | U13: =if(O13,_xlfn.WORKDAY.INTL(O13,U$5,"1000000",Holidays!A:A)+hour(O13)/24+MINUTE(O13)/1440,"") -> 44629.523 | V13: =if(V13,V13,if(W13<>"",$A$1,"")) -> 44924.794 | W13: done | X13: =if(U13,if(V13<>"",if(V13>U13,V13-U13,""),$A$1-U13),"") -> 295.27092 | Y13: done | AB13: 1 | AC13: 2 | AD13: 3 | AH13: =IF(P13="","",P13+AB13+AC13+AD13+AE13+AF13) -> 44750.459 | AI13: =if(AH13,_xlfn.workday.intl(int(AH13),0,"1000000",Holidays!A:A)+18/24,"") -> 44750.75 | AJ13: =if(AJ13,AJ13,if(AK13<>"",$A$1,"")) -> 44733.663 | AK13: done | AL13: =if(AI13,if(AJ13<>"",if(AJ13>AI13,AJ13-AI13,""),$A$1-AI13),"") | AN13: =if(AJ13,if(and(hour(AJ13+AN$5)>11,(hour(AJ13+AN$5)<20)),AJ13+AN$5,_xlfn.workday.intl(int(AJ13),1,"1000000",Holidays!A:A)+hour(AJ13+AN$5-$B$1)/24+minute(AJ13)/1440),"") -> 44734.663 | AO13: =if(AO13,AO13,if(AP13<>"",$A$1,"")) -> 44744.459 | AP13: done | AQ13: =if(AN13,if(AO13<>"",if(AO13>AN13,AO13-AN13,""),$A$1-AN13),"") -> 9.7955569 | AS13: =if(AJ13,if(and(hour(AJ13+AS$5)>11,(hour(AJ13+AS$5)<20)),AJ13+AS$5,_xlfn.workday.intl(int(AJ13),1,"1000000",Holidays!A:A)+hour(AJ13+AS$5-$B$1)/24+minute(AJ13)/1440),"") -> 44735.663 | AT13: =if(AT13,AT13,if(AU13<>"",$A$1,"")) -> 44744.459 | AU13: yes | AV13: =if(AS13,if(AT13<>"",if(AT13>AS13,AT13-AS13,""),$A$1-AS13),"") -> 8.795586 | AX13: done
A14: 44626.526 | G14: =if(A14,_xlfn.workday.intl(int(A14),1,"1000000",Holidays!A:A)+17/24,"") -> 44628.708 | H14: =if(H14,H14,if(I14<>"",$A$1,"")) -> 44744.458 | I14: done | J14: =if(G14,if(H14<>"",if(H14>G14,H14-G14,""),$A$1-G14),"") -> 115.7497 | K14: =if(G14,_xlfn.workday.intl(int(G14),0,"1000000",Holidays!A:A)+19/24,"") -> 44628.792 | L14: =if(L14,L14,if(M14<>"",$A$1,"")) -> 44744.458 | M14: done | N14: =if(K14,if(L14<>"",if(L14>K14,L14-K14,""),$A$1-K14),"") -> 115.6664 | O14: =if(A14,_xlfn.WORKDAY.INTL(A14,O$5,"1000000",Holidays!A:A)+hour(A14)/24+MINUTE(A14)/1440,"") -> 44628.525 | P14: 44744.458 | Q14: done | R14: =if(O14,if(P14<>"",if(P14>O14,P14-O14,""),$A$1-O14),"") -> 115.93313 | T14: done | U14: =if(O14,_xlfn.WORKDAY.INTL(O14,U$5,"1000000",Holidays!A:A)+hour(O14)/24+MINUTE(O14)/1440,"") -> 44629.525 | V14: =if(V14,V14,if(W14<>"",$A$1,"")) -> 44924.794 | W14: done | X14: =if(U14,if(V14<>"",if(V14>U14,V14-U14,""),$A$1-U14),"") -> 295.26889 | Y14: done | AB14: 1 | AC14: 2 | AD14: 3 | AH14: =IF(P14="","",P14+AB14+AC14+AD14+AE14+AF14) -> 44750.458 | AI14: =if(AH14,_xlfn.workday.intl(int(AH14),0,"1000000",Holidays!A:A)+18/24,"") -> 44750.75 | AJ14: =if(AJ14,AJ14,if(AK14<>"",$A$1,"")) -> 44733.663 | AK14: done | AL14: =if(AI14,if(AJ14<>"",if(AJ14>AI14,AJ14-AI14,""),$A$1-AI14),"") | AN14: =if(AJ14,if(and(hour(AJ14+AN$5)>11,(hour(AJ14+AN$5)<20)),AJ14+AN$5,_xlfn.workday.intl(int(AJ14),1,"1000000",Holidays!A:A)+hour(AJ14+AN$5-$B$1)/24+minute(AJ14)/1440),"") -> 44734.663 | AO14: =if(AO14,AO14,if(AP14<>"",$A$1,"")) -> 44744.458 | AP14: done | AQ14: =if(AN14,if(AO14<>"",if(AO14>AN14,AO14-AN14,""),$A$1-AN14),"") -> 9.7951225 | AS14: =if(AJ14,if(and(hour(AJ14+AS$5)>11,(hour(AJ14+AS$5)<20)),AJ14+AS$5,_xlfn.workday.intl(int(AJ14),1,"1000000",Holidays!A:A)+hour(AJ14+AS$5-$B$1)/24+minute(AJ14)/1440),"") -> 44735.663 | AT14: =if(AT14,AT14,if(AU14<>"",$A$1,"")) -> 44744.458 | AU14: yes | AV14: =if(AS14,if(AT14<>"",if(AT14>AS14,AT14-AS14,""),$A$1-AS14),"") -> 8.795186 | AX14: done
A15: 44626.528 | G15: =if(A15,_xlfn.workday.intl(int(A15),1,"1000000",Holidays!A:A)+17/24,"") -> 44628.708 | H15: =if(H15,H15,if(I15<>"",$A$1,"")) -> 44744.458 | I15: done | J15: =if(G15,if(H15<>"",if(H15>G15,H15-G15,""),$A$1-G15),"") -> 115.74939 | K15: =if(G15,_xlfn.workday.intl(int(G15),0,"1000000",Holidays!A:A)+19/24,"") -> 44628.792 | L15: =if(L15,L15,if(M15<>"",$A$1,"")) -> 44744.458 | M15: done | N15: =if(K15,if(L15<>"",if(L15>K15,L15-K15,""),$A$1-K15),"") -> 115.66609 | O15: =if(A15,_xlfn.WORKDAY.INTL(A15,O$5,"1000000",Holidays!A:A)+hour(A15)/24+MINUTE(A15)/1440,"") -> 44628.528 | P15: 44744.458 | Q15: done | R15: =if(O15,if(P15<>"",if(P15>O15,P15-O15,""),$A$1-O15),"") -> 115.93001 | T15: done | U15: =if(O15,_xlfn.WORKDAY.INTL(O15,U$5,"1000000",Holidays!A:A)+hour(O15)/24+MINUTE(O15)/1440,"") -> 44629.528 | V15: =if(V15,V15,if(W15<>"",$A$1,"")) -> 44924.794 | W15: done | X15: =if(U15,if(V15<>"",if(V15>U15,V15-U15,""),$A$1-U15),"") -> 295.26608 | Y15: done | AB15: 1 | AC15: 2 | AD15: 3 | AH15: =IF(P15="","",P15+AB15+AC15+AD15+AE15+AF15) -> 44750.458 | AI15: =if(AH15,_xlfn.workday.intl(int(AH15),0,"1000000",Holidays!A:A)+18/24,"") -> 44750.75 | AJ15: =if(AJ15,AJ15,if(AK15<>"",$A$1,"")) -> 44733.663 | AK15: done | AL15: =if(AI15,if(AJ15<>"",if(AJ15>AI15,AJ15-AI15,""),$A$1-AI15),"") | AN15: =if(AJ15,if(and(hour(AJ15+AN$5)>11,(hour(AJ15+AN$5)<20)),AJ15+AN$5,_xlfn.workday.intl(int(AJ15),1,"1000000",Holidays!A:A)+hour(AJ15+AN$5-$B$1)/24+minute(AJ15)/1440),"") -> 44734.663 | AO15: =if(AO15,AO15,if(AP15<>"",$A$1,"")) -> 44744.458 | AP15: done | AQ15: =if(AN15,if(AO15<>"",if(AO15>AN15,AO15-AN15,""),$A$1-AN15),"") -> 9.7946667 | AS15: =if(AJ15,if(and(hour(AJ15+AS$5)>11,(hour(AJ15+AS$5)<20)),AJ15+AS$5,_xlfn.workday.intl(int(AJ15),1,"1000000",Holidays!A:A)+hour(AJ15+AS$5-$B$1)/24+minute(AJ15)/1440),"") -> 44735.663 | AT15: =if(AT15,AT15,if(AU15<>"",$A$1,"")) -> 44744.458 | AU15: yes | AV15: =if(AS15,if(AT15<>"",if(AT15>AS15,AT15-AS15,""),$A$1-AS15),"") -> 8.7946953 | AX15: done
A16: 44626.666 | G16: =if(A16,_xlfn.workday.intl(int(A16),1,"1000000",Holidays!A:A)+17/24,"") -> 44628.708 | H16: =if(H16,H16,if(I16<>"",$A$1,"")) -> 44744.457 | I16: done | J16: =if(G16,if(H16<>"",if(H16>G16,H16-G16,""),$A$1-G16),"") -> 115.74905 | K16: =if(G16,_xlfn.workday.intl(int(G16),0,"1000000",Holidays!A:A)+19/24,"") -> 44628.792 | L16: =if(L16,L16,if(M16<>"",$A$1,"")) -> 44744.457 | M16: done | N16: =if(K16,if(L16<>"",if(L16>K16,L16-K16,""),$A$1-K16),"") -> 115.66577 | O16: =if(A16,_xlfn.WORKDAY.INTL(A16,O$5,"1000000",Holidays!A:A)+hour(A16)/24+MINUTE(A16)/1440,"") -> 44628.666 | P16: 44744.458 | Q16: done | R16: =if(O16,if(P16<>"",if(P16>O16,P16-O16,""),$A$1-O16),"") -> 115.79155 | T16: done | U16: =if(O16,_xlfn.WORKDAY.INTL(O16,U$5,"1000000",Holidays!A:A)+hour(O16)/24+MINUTE(O16)/1440,"") -> 44629.666 | V16: =if(V16,V16,if(W16<>"",$A$1,"")) -> 44924.794 | W16: done | X16: =if(U16,if(V16<>"",if(V16>U16,V16-U16,""),$A$1-U16),"") -> 295.12842 | Y16: done | AB16: 1 | AC16: 2 | AD16: 3 | AH16: =IF(P16="","",P16+AB16+AC16+AD16+AE16+AF16) -> 44750.458 | AI16: =if(AH16,_xlfn.workday.intl(int(AH16),0,"1000000",Holidays!A:A)+18/24,"") -> 44750.75 | AJ16: =if(AJ16,AJ16,if(AK16<>"",$A$1,"")) -> 44744.458 | AK16: done | AL16: =if(AI16,if(AJ16<>"",if(AJ16>AI16,AJ16-AI16,""),$A$1-AI16),"") | AN16: =if(AJ16,if(and(hour(AJ16+AN$5)>11,(hour(AJ16+AN$5)<20)),AJ16+AN$5,_xlfn.workday.intl(int(AJ16),1,"1000000",Holidays!A:A)+hour(AJ16+AN$5-$B$1)/24+minute(AJ16)/1440),"") -> 44745.457 | AO16: =if(AO16,AO16,if(AP16<>"",$A$1,"")) -> 44744.458 | AP16: done | AQ16: =if(AN16,if(AO16<>"",if(AO16>AN16,AO16-AN16,""),$A$1-AN16),"") | AS16: =if(AJ16,if(and(hour(AJ16+AS$5)>11,(hour(AJ16+AS$5)<20)),AJ16+AS$5,_xlfn.workday.intl(int(AJ16),1,"1000000",Holidays!A:A)+hour(AJ16+AS$5-$B$1)/24+minute(AJ16)/1440),"") -> 44745.457 | AT16: =if(AT16,AT16,if(AU16<>"",$A$1,"")) -> 44744.458 | AU16: yes | AV16: =if(AS16,if(AT16<>"",if(AT16>AS16,AT16-AS16,""),$A$1-AS16),"") | AX16: done
A17: 44626.668 | G17: =if(A17,_xlfn.workday.intl(int(A17),1,"1000000",Holidays!A:A)+17/24,"") -> 44628.708 | H17: =if(H17,H17,if(I17<>"",$A$1,"")) | J17: =if(G17,if(H17<>"",if(H17>G17,H17-G17,""),$A$1-G17),"") -> 1505.2756 | K17: =if(G17,_xlfn.workday.intl(int(G17),0,"1000000",Holidays!A:A)+19/24,"") -> 44628.792 | L17: =if(L17,L17,if(M17<>"",$A$1,"")) | N17: =if(K17,if(L17<>"",if(L17>K17,L17-K17,""),$A$1-K17),"") -> 1505.1922 | O17: =if(A17,_xlfn.WORKDAY.INTL(A17,O$5,"1000000",Holidays!A:A)+hour(A17)/24+MINUTE(A17)/1440,"") -> 44628.668 | R17: =if(O17,if(P17<>"",if(P17>O17,P17-O17,""),$A$1-O17),"") -> 1505.3159 | U17: =if(O17,_xlfn.WORKDAY.INTL(O17,U$5,"1000000",Holidays!A:A)+hour(O17)/24+MINUTE(O17)/1440,"") -> 44629.668 | V17: =if(V17,V17,if(W17<>"",$A$1,"")) | X17: =if(U17,if(V17<>"",if(V17>U17,V17-U17,""),$A$1-U17),"") -> 1504.3159 | AH17: =IF(P17="","",P17+AB17+AC17+AD17+AE17+AF17) | AI17: =if(AH17,_xlfn.workday.intl(int(AH17),0,"1000000",Holidays!A:A)+18/24,"") | AJ17: =if(AJ17,AJ17,if(AK17<>"",$A$1,"")) | AL17: =if(AI17,if(AJ17<>"",if(AJ17>AI17,AJ17-AI17,""),$A$1-AI17),"") | AN17: =if(AJ17,if(and(hour(AJ17+AN$5)>11,(hour(AJ17+AN$5)<20)),AJ17+AN$5,_xlfn.workday.intl(int(AJ17),1,"1000000",Holidays!A:A)+hour(AJ17+AN$5-$B$1)/24+minute(AJ17)/1440),"") | AS17: =if(AJ17,if(and(hour(AJ17+AS$5)>11,(hour(AJ17+AS$5)<20)),AJ17+AS$5,_xlfn.workday.intl(int(AJ17),1,"1000000",Holidays!A:A)+hour(AJ17+AS$5-$B$1)/24+minute(AJ17)/1440),"") | AT17: =if(AT17,AT17,if(AU17<>"",$A$1,"")) | AV17: =if(AS17,if(AT17<>"",if(AT17>AS17,AT17-AS17,""),$A$1-AS17),"") | AX17: No Response
A18: 44626.669 | G18: =if(A18,_xlfn.workday.intl(int(A18),1,"1000000",Holidays!A:A)+17/24,"") -> 44628.708 | H18: =if(H18,H18,if(I18<>"",$A$1,"")) | J18: =if(G18,if(H18<>"",if(H18>G18,H18-G18,""),$A$1-G18),"") -> 1505.2756 | K18: =if(G18,_xlfn.workday.intl(int(G18),0,"1000000",Holidays!A:A)+19/24,"") -> 44628.792 | L18: =if(L18,L18,if(M18<>"",$A$1,"")) | N18: =if(K18,if(L18<>"",if(L18>K18,L18-K18,""),$A$1-K18),"") -> 1505.1922 | O18: =if(A18,_xlfn.WORKDAY.INTL(A18,O$5,"1000000",Holidays!A:A)+hour(A18)/24+MINUTE(A18)/1440,"") -> 44628.669 | R18: =if(O18,if(P18<>"",if(P18>O18,P18-O18,""),$A$1-O18),"") -> 1505.3152 | U18: =if(O18,_xlfn.WORKDAY.INTL(O18,U$5,"1000000",Holidays!A:A)+hour(O18)/24+MINUTE(O18)/1440,"") -> 44629.669 | V18: =if(V18,V18,if(W18<>"",$A$1,"")) | X18: =if(U18,if(V18<>"",if(V18>U18,V18-U18,""),$A$1-U18),"") -> 1504.3152 | AH18: =IF(P18="","",P18+AB18+AC18+AD18+AE18+AF18) | AI18: =if(AH18,_xlfn.workday.intl(int(AH18),0,"1000000",Holidays!A:A)+18/24,"") | AJ18: =if(AJ18,AJ18,if(AK18<>"",$A$1,"")) | AL18: =if(AI18,if(AJ18<>"",if(AJ18>AI18,AJ18-AI18,""),$A$1-AI18),"") | AN18: =if(AJ18,if(and(hour(AJ18+AN$5)>11,(hour(AJ18+AN$5)<20)),AJ18+AN$5,_xlfn.workday.intl(int(AJ18),1,"1000000",Holidays!A:A)+hour(AJ18+AN$5-$B$1)/24+minute(AJ18)/1440),"") | AO18: =if(AO18,AO18,if(AP18<>"",$A$1,"")) | AQ18: =if(AN18,if(AO18<>"",if(AO18>AN18,AO18-AN18,""),$A$1-AN18),"") | AS18: =if(AJ18,if(and(hour(AJ18+AS$5)>11,(hour(AJ18+AS$5)<20)),AJ18+AS$5,_xlfn.workday.intl(int(AJ18),1,"1000000",Holidays!A:A)+hour(AJ18+AS$5-$B$1)/24+minute(AJ18)/1440),"") | AT18: =if(AT18,AT18,if(AU18<>"",$A$1,"")) | AV18: =if(AS18,if(AT18<>"",if(AT18>AS18,AT18-AS18,""),$A$1-AS18),"") | AX18: No Response
A19: 44626.671 | G19: =if(A19,_xlfn.workday.intl(int(A19),1,"1000000",Holidays!A:A)+17/24,"") -> 44628.708 | H19: =if(H19,H19,if(I19<>"",$A$1,"")) | J19: =if(G19,if(H19<>"",if(H19>G19,H19-G19,""),$A$1-G19),"") -> 1505.2756 | K19: =if(G19,_xlfn.workday.intl(int(G19),0,"1000000",Holidays!A:A)+19/24,"") -> 44628.792 | L19: =if(L19,L19,if(M19<>"",$A$1,"")) | N19: =if(K19,if(L19<>"",if(L19>K19,L19-K19,""),$A$1-K19),"") -> 1505.1922 | O19: =if(A19,_xlfn.WORKDAY.INTL(A19,O$5,"1000000",Holidays!A:A)+hour(A19)/24+MINUTE(A19)/1440,"") -> 44628.671 | R19: =if(O19,if(P19<>"",if(P19>O19,P19-O19,""),$A$1-O19),"") -> 1505.3131 | U19: =if(O19,_xlfn.WORKDAY.INTL(O19,U$5,"1000000",Holidays!A:A)+hour(O19)/24+MINUTE(O19)/1440,"") -> 44629.671 | V19: =if(V19,V19,if(W19<>"",$A$1,"")) | X19: =if(U19,if(V19<>"",if(V19>U19,V19-U19,""),$A$1-U19),"") -> 1504.3131 | AH19: =IF(P19="","",P19+AB19+AC19+AD19+AE19+AF19) | AI19: =if(AH19,_xlfn.workday.intl(int(AH19),0,"1000000",Holidays!A:A)+18/24,"") | AJ19: =if(AJ19,AJ19,if(AK19<>"",$A$1,"")) | AL19: =if(AI19,if(AJ19<>"",if(AJ19>AI19,AJ19-AI19,""),$A$1-AI19),"") | AN19: =if(AJ19,if(and(hour(AJ19+AN$5)>11,(hour(AJ19+AN$5)<20)),AJ19+AN$5,_xlfn.workday.intl(int(AJ19),1,"1000000",Holidays!A:A)+hour(AJ19+AN$5-$B$1)/24+minute(AJ19)/1440),"") | AO19: =if(AO19,AO19,if(AP19<>"",$A$1,"")) | AQ19: =if(AN19,if(AO19<>"",if(AO19>AN19,AO19-AN19,""),$A$1-AN19),"") | AS19: =if(AJ19,if(and(hour(AJ19+AS$5)>11,(hour(AJ19+AS$5)<20)),AJ19+AS$5,_xlfn.workday.intl(int(AJ19),1,"1000000",Holidays!A:A)+hour(AJ19+AS$5-$B$1)/24+minute(AJ19)/1440),"") | AT19: =if(AT19,AT19,if(AU19<>"",$A$1,"")) | AV19: =if(AS19,if(AT19<>"",if(AT19>AS19,AT19-AS19,""),$A$1-AS19),"") | AX19: No Response
A20: 44626.673 | G20: =if(A20,_xlfn.workday.intl(int(A20),1,"1000000",Holidays!A:A)+17/24,"") -> 44628.708 | H20: =if(H20,H20,if(I20<>"",$A$1,"")) -> 44744.457 | I20: done | J20: =if(G20,if(H20<>"",if(H20>G20,H20-G20,""),$A$1-G20),"") -> 115.74833 | K20: =if(G20,_xlfn.workday.intl(int(G20),0,"1000000",Holidays!A:A)+19/24,"") -> 44628.792 | L20: =if(L20,L20,if(M20<>"",$A$1,"")) -> 44744.457 | M20: done | N20: =if(K20,if(L20<>"",if(L20>K20,L20-K20,""),$A$1-K20),"") -> 115.66503 | O20: =if(A20,_xlfn.WORKDAY.INTL(A20,O$5,"1000000",Holidays!A:A)+hour(A20)/24+MINUTE(A20)/1440,"") -> 44628.673 | P20: 44744.457 | Q20: done | R20: =if(O20,if(P20<>"",if(P20>O20,P20-O20,""),$A$1-O20),"") -> 115.78381 | T20: done | U20: =if(O20,_xlfn.WORKDAY.INTL(O20,U$5,"1000000",Holidays!A:A)+hour(O20)/24+MINUTE(O20)/1440,"") -> 44629.673 | V20: =if(V20,V20,if(W20<>"",$A$1,"")) -> 44924.796 | W20: done | X20: =if(U20,if(V20<>"",if(V20>U20,V20-U20,""),$A$1-U20),"") -> 295.12264 | Y20: done | AB20: 1 | AC20: 2 | AD20: 3 | AH20: =IF(P20="","",P20+AB20+AC20+AD20+AE20+AF20) -> 44750.457 | AI20: =if(AH20,_xlfn.workday.intl(int(AH20),0,"1000000",Holidays!A:A)+18/24,"") -> 44750.75 | AJ20: =if(AJ20,AJ20,if(AK20<>"",$A$1,"")) -> 44733.664 | AK20: done | AL20: =if(AI20,if(AJ20<>"",if(AJ20>AI20,AJ20-AI20,""),$A$1-AI20),"") | AN20: =if(AJ20,if(and(hour(AJ20+AN$5)>11,(hour(AJ20+AN$5)<20)),AJ20+AN$5,_xlfn.workday.intl(int(AJ20),1,"1000000",Holidays!A:A)+hour(AJ20+AN$5-$B$1)/24+minute(AJ20)/1440),"") -> 44734.664 | AO20: =if(AO20,AO20,if(AP20<>"",$A$1,"")) -> 44744.457 | AP20: done | AQ20: =if(AN20,if(AO20<>"",if(AO20>AN20,AO20-AN20,""),$A$1-AN20),"") -> 9.7932748 | AS20: =if(AJ20,if(and(hour(AJ20+AS$5)>11,(hour(AJ20+AS$5)<20)),AJ20+AS$5,_xlfn.workday.intl(int(AJ20),1,"1000000",Holidays!A:A)+hour(AJ20+AS$5-$B$1)/24+minute(AJ20)/1440),"") -> 44735.664 | AT20: =if(AT20,AT20,if(AU20<>"",$A$1,"")) -> 44744.457 | AU20: yes | AV20: =if(AS20,if(AT20<>"",if(AT20>AS20,AT20-AS20,""),$A$1-AS20),"") -> 8.7933066 | AX20: done
A21: 44628.493 | G21: =if(A21,_xlfn.workday.intl(int(A21),1,"1000000",Holidays!A:A)+17/24,"") -> 44629.708 | H21: =if(H21,H21,if(I21<>"",$A$1,"")) -> 44744.456 | I21: done | J21: =if(G21,if(H21<>"",if(H21>G21,H21-G21,""),$A$1-G21),"") -> 114.74804 | K21: =if(G21,_xlfn.workday.intl(int(G21),0,"1000000",Holidays!A:A)+19/24,"") -> 44629.792 | L21: =if(L21,L21,if(M21<>"",$A$1,"")) -> 44744.456 | M21: done | N21: =if(K21,if(L21<>"",if(L21>K21,L21-K21,""),$A$1-K21),"") -> 114.66477 | O21: =if(A21,_xlfn.WORKDAY.INTL(A21,O$5,"1000000",Holidays!A:A)+hour(A21)/24+MINUTE(A21)/1440,"") -> 44629.492 | P21: 44744.456 | Q21: done | R21: =if(O21,if(P21<>"",if(P21>O21,P21-O21,""),$A$1-O21),"") -> 114.96412 | T21: done | U21: =if(O21,_xlfn.WORKDAY.INTL(O21,U$5,"1000000",Holidays!A:A)+hour(O21)/24+MINUTE(O21)/1440,"") -> 44630.492 | V21: =if(V21,V21,if(W21<>"",$A$1,"")) -> 44924.796 | W21: done | X21: =if(U21,if(V21<>"",if(V21>U21,V21-U21,""),$A$1-U21),"") -> 294.30317 | Y21: done | AB21: 1 | AC21: 2 | AD21: 3 | AH21: =IF(P21="","",P21+AB21+AC21+AD21+AE21+AF21) -> 44750.456 | AI21: =if(AH21,_xlfn.workday.intl(int(AH21),0,"1000000",Holidays!A:A)+18/24,"") -> 44750.75 | AJ21: =if(AJ21,AJ21,if(AK21<>"",$A$1,"")) -> 44733.664 | AK21: done | AL21: =if(AI21,if(AJ21<>"",if(AJ21>AI21,AJ21-AI21,""),$A$1-AI21),"") | AN21: =if(AJ21,if(and(hour(AJ21+AN$5)>11,(hour(AJ21+AN$5)<20)),AJ21+AN$5,_xlfn.workday.intl(int(AJ21),1,"1000000",Holidays!A:A)+hour(AJ21+AN$5-$B$1)/24+minute(AJ21)/1440),"") -> 44734.664 | AO21: =if(AO21,AO21,if(AP21<>"",$A$1,"")) -> 44744.457 | AP21: done | AQ21: =if(AN21,if(AO21<>"",if(AO21>AN21,AO21-AN21,""),$A$1-AN21),"") -> 9.7929588 | AS21: =if(AJ21,if(and(hour(AJ21+AS$5)>11,(hour(AJ21+AS$5)<20)),AJ21+AS$5,_xlfn.workday.intl(int(AJ21),1,"1000000",Holidays!A:A)+hour(AJ21+AS$5-$B$1)/24+minute(AJ21)/1440),"") -> 44735.664 | AT21: =if(AT21,AT21,if(AU21<>"",$A$1,"")) -> 44744.457 | AU21: yes | AV21: =if(AS21,if(AT21<>"",if(AT21>AS21,AT21-AS21,""),$A$1-AS21),"") -> 8.7929912 | AX21: done
A22: 44629.479 | G22: =if(A22,_xlfn.workday.intl(int(A22),1,"1000000",Holidays!A:A)+17/24,"") -> 44630.708 | H22: =if(H22,H22,if(I22<>"",$A$1,"")) -> 44744.456 | I22: done | J22: =if(G22,if(H22<>"",if(H22>G22,H22-G22,""),$A$1-G22),"") -> 113.74771 | K22: =if(G22,_xlfn.workday.intl(int(G22),0,"1000000",Holidays!A:A)+19/24,"") -> 44630.792 | L22: =if(L22,L22,if(M22<>"",$A$1,"")) -> 44744.456 | M22: done | N22: =if(K22,if(L22<>"",if(L22>K22,L22-K22,""),$A$1-K22),"") -> 113.6644 | O22: =if(A22,_xlfn.WORKDAY.INTL(A22,O$5,"1000000",Holidays!A:A)+hour(A22)/24+MINUTE(A22)/1440,"") -> 44630.478 | P22: 44744.456 | Q22: done | R22: =if(O22,if(P22<>"",if(P22>O22,P22-O22,""),$A$1-O22),"") -> 113.97762 | T22: done | U22: =if(O22,_xlfn.WORKDAY.INTL(O22,U$5,"1000000",Holidays!A:A)+hour(O22)/24+MINUTE(O22)/1440,"") -> 44631.478 | V22: =if(V22,V22,if(W22<>"",$A$1,"")) -> 44924.796 | W22: done | X22: =if(U22,if(V22<>"",if(V22>U22,V22-U22,""),$A$1-U22),"") -> 293.31704 | Y22: done | AB22: 1 | AC22: 2 | AD22: 3 | AH22: =IF(P22="","",P22+AB22+AC22+AD22+AE22+AF22) -> 44750.456 | AI22: =if(AH22,_xlfn.workday.intl(int(AH22),0,"1000000",Holidays!A:A)+18/24,"") -> 44750.75 | AJ22: =if(AJ22,AJ22,if(AK22<>"",$A$1,"")) -> 44733.664 | AK22: done | AL22: =if(AI22,if(AJ22<>"",if(AJ22>AI22,AJ22-AI22,""),$A$1-AI22),"") | AN22: =if(AJ22,if(and(hour(AJ22+AN$5)>11,(hour(AJ22+AN$5)<20)),AJ22+AN$5,_xlfn.workday.intl(int(AJ22),1,"1000000",Holidays!A:A)+hour(AJ22+AN$5-$B$1)/24+minute(AJ22)/1440),"") -> 44734.664 | AO22: =if(AO22,AO22,if(AP22<>"",$A$1,"")) -> 44744.456 | AP22: done | AQ22: =if(AN22,if(AO22<>"",if(AO22>AN22,AO22-AN22,""),$A$1-AN22),"") -> 9.7925208 | AS22: =if(AJ22,if(and(hour(AJ22+AS$5)>11,(hour(AJ22+AS$5)<20)),AJ22+AS$5,_xlfn.workday.intl(int(AJ22),1,"1000000",Holidays!A:A)+hour(AJ22+AS$5-$B$1)/24+minute(AJ22)/1440),"") -> 44735.664 | AT22: =if(AT22,AT22,if(AU22<>"",$A$1,"")) -> 44744.456 | AU22: yes | AV22: =if(AS22,if(AT22<>"",if(AT22>AS22,AT22-AS22,""),$A$1-AS22),"") -> 8.7925522 | AX22: done
A23: 44635.722 | G23: =if(A23,_xlfn.workday.intl(int(A23),1,"1000000",Holidays!A:A)+17/24,"") -> 44636.708 | H23: =if(H23,H23,if(I23<>"",$A$1,"")) | J23: =if(G23,if(H23<>"",if(H23>G23,H23-G23,""),$A$1-G23),"") -> 1497.2756 | K23: =if(G23,_xlfn.workday.intl(int(G23),0,"1000000",Holidays!A:A)+19/24,"") -> 44636.792 | L23: =if(L23,L23,if(M23<>"",$A$1,"")) | N23: =if(K23,if(L23<>"",if(L23>K23,L23-K23,""),$A$1-K23),"") -> 1497.1922 | O23: =if(A23,_xlfn.WORKDAY.INTL(A23,O$5,"1000000",Holidays!A:A)+hour(A23)/24+MINUTE(A23)/1440,"") -> 44636.722 | R23: =if(O23,if(P23<>"",if(P23>O23,P23-O23,""),$A$1-O23),"") -> 1497.2624 | U23: =if(O23,_xlfn.WORKDAY.INTL(O23,U$5,"1000000",Holidays!A:A)+hour(O23)/24+MINUTE(O23)/1440,"") -> 44637.722 | V23: =if(V23,V23,if(W23<>"",$A$1,"")) | X23: =if(U23,if(V23<>"",if(V23>U23,V23-U23,""),$A$1-U23),"") -> 1496.2624 | AH23: =IF(P23="","",P23+AB23+AC23+AD23+AE23+AF23) | AI23: =if(AH23,_xlfn.workday.intl(int(AH23),0,"1000000",Holidays!A:A)+18/24,"") | AJ23: =if(AJ23,AJ23,if(AK23<>"",$A$1,"")) | AL23: =if(AI23,if(AJ23<>"",if(AJ23>AI23,AJ23-AI23,""),$A$1-AI23),"") | AN23: =if(AJ23,if(and(hour(AJ23+AN$5)>11,(hour(AJ23+AN$5)<20)),AJ23+AN$5,_xlfn.workday.intl(int(AJ23),1,"1000000",Holidays!A:A)+hour(AJ23+AN$5-$B$1)/24+minute(AJ23)/1440),"") | AO23: =if(AO23,AO23,if(AP23<>"",$A$1,"")) | AQ23: =if(AN23,if(AO23<>"",if(AO23>AN23,AO23-AN23,""),$A$1-AN23),"") | AS23: =if(AJ23,if(and(hour(AJ23+AS$5)>11,(hour(AJ23+AS$5)<20)),AJ23+AS$5,_xlfn.workday.intl(int(AJ23),1,"1000000",Holidays!A:A)+hour(AJ23+AS$5-$B$1)/24+minute(AJ23)/1440),"") | AT23: =if(AT23,AT23,if(AU23<>"",$A$1,"")) | AV23: =if(AS23,if(AT23<>"",if(AT23>AS23,AT23-AS23,""),$A$1-AS23),"") | AX23: Hold
A24: 44636.493 | G24: =if(A24,_xlfn.workday.intl(int(A24),1,"1000000",Holidays!A:A)+17/24,"") -> 44637.708 | H24: =if(H24,H24,if(I24<>"",$A$1,"")) -> 44744.455 | I24: done | J24: =if(G24,if(H24<>"",if(H24>G24,H24-G24,""),$A$1-G24),"") -> 106.74716 | K24: =if(G24,_xlfn.workday.intl(int(G24),0,"1000000",Holidays!A:A)+19/24,"") -> 44637.792 | L24: =if(L24,L24,if(M24<>"",$A$1,"")) -> 44744.456 | M24: done | N24: =if(K24,if(L24<>"",if(L24>K24,L24-K24,""),$A$1-K24),"") -> 106.66386 | O24: =if(A24,_xlfn.WORKDAY.INTL(A24,O$5,"1000000",Holidays!A:A)+hour(A24)/24+MINUTE(A24)/1440,"") -> 44637.492 | P24: 44744.456 | Q24: done | R24: =if(O24,if(P24<>"",if(P24>O24,P24-O24,""),$A$1-O24),"") -> 106.9632 | T24: done | U24: =if(O24,_xlfn.WORKDAY.INTL(O24,U$5,"1000000",Holidays!A:A)+hour(O24)/24+MINUTE(O24)/1440,"") -> 44638.492 | V24: =if(V24,V24,if(W24<>"",$A$1,"")) -> 44924.796 | W24: done | X24: =if(U24,if(V24<>"",if(V24>U24,V24-U24,""),$A$1-U24),"") -> 286.30366 | Y24: done | AB24: 1 | AC24: 2 | AH24: =IF(P24="","",P24+AB24+AC24+AD24+AE24+AF24) -> 44747.456 | AI24: =if(AH24,_xlfn.workday.intl(int(AH24),0,"1000000",Holidays!A:A)+18/24,"") -> 44747.75 | AJ24: =if(AJ24,AJ24,if(AK24<>"",$A$1,"")) -> 44733.664 | AK24: done | AL24: =if(AI24,if(AJ24<>"",if(AJ24>AI24,AJ24-AI24,""),$A$1-AI24),"") | AN24: =if(AJ24,if(and(hour(AJ24+AN$5)>11,(hour(AJ24+AN$5)<20)),AJ24+AN$5,_xlfn.workday.intl(int(AJ24),1,"1000000",Holidays!A:A)+hour(AJ24+AN$5-$B$1)/24+minute(AJ24)/1440),"") -> 44734.664 | AO24: =if(AO24,AO24,if(AP24<>"",$A$1,"")) -> 44744.456 | AP24: done | AQ24: =if(AN24,if(AO24<>"",if(AO24>AN24,AO24-AN24,""),$A$1-AN24),"") -> 9.7916254 | AS24: =if(AJ24,if(and(hour(AJ24+AS$5)>11,(hour(AJ24+AS$5)<20)),AJ24+AS$5,_xlfn.workday.intl(int(AJ24),1,"1000000",Holidays!A:A)+hour(AJ24+AS$5-$B$1)/24+minute(AJ24)/1440),"") -> 44735.664 | AT24: =if(AT24,AT24,if(AU24<>"",$A$1,"")) -> 44744.456 | AU24: yes | AV24: =if(AS24,if(AT24<>"",if(AT24>AS24,AT24-AS24,""),$A$1-AS24),"") -> 8.7916652 | AX24: done
A25: 44636.495 | G25: =if(A25,_xlfn.workday.intl(int(A25),1,"1000000",Holidays!A:A)+17/24,"") -> 44637.708 | H25: =if(H25,H25,if(I25<>"",$A$1,"")) | J25: =if(G25,if(H25<>"",if(H25>G25,H25-G25,""),$A$1-G25),"") -> 1496.2756 | K25: =if(G25,_xlfn.workday.intl(int(G25),0,"1000000",Holidays!A:A)+19/24,"") -> 44637.792 | L25: =if(L25,L25,if(M25<>"",$A$1,"")) -> 44744.776 | M25: done | N25: =if(K25,if(L25<>"",if(L25>K25,L25-K25,""),$A$1-K25),"") -> 106.98472 | O25: =if(A25,_xlfn.WORKDAY.INTL(A25,O$5,"1000000",Holidays!A:A)+hour(A25)/24+MINUTE(A25)/1440,"") -> 44637.494 | P25: 44744.455 | Q25: done | R25: =if(O25,if(P25<>"",if(P25>O25,P25-O25,""),$A$1-O25),"") -> 106.96079 | T25: done | U25: =if(O25,_xlfn.WORKDAY.INTL(O25,U$5,"1000000",Holidays!A:A)+hour(O25)/24+MINUTE(O25)/1440,"") -> 44638.494 | V25: =if(V25,V25,if(W25<>"",$A$1,"")) -> 44924.796 | W25: done | X25: =if(U25,if(V25<>"",if(V25>U25,V25-U25,""),$A$1-U25),"") -> 286.3016 | Y25: done | AB25: 6 | AC25: 1 | AH25: =IF(P25="","",P25+AB25+AC25+AD25+AE25+AF25) -> 44751.455 | AI25: =if(AH25,_xlfn.workday.intl(int(AH25),0,"1000000",Holidays!A:A)+18/24,"") -> 44751.75 | AJ25: =if(AJ25,AJ25,if(AK25<>"",$A$1,"")) -> 44733.665 | AK25: done | AL25: =if(AI25,if(AJ25<>"",if(AJ25>AI25,AJ25-AI25,""),$A$1-AI25),"") | AN25: =if(AJ25,if(and(hour(AJ25+AN$5)>11,(hour(AJ25+AN$5)<20)),AJ25+AN$5,_xlfn.workday.intl(int(AJ25),1,"1000000",Holidays!A:A)+hour(AJ25+AN$5-$B$1)/24+minute(AJ25)/1440),"") -> 44734.665 | AO25: =if(AO25,AO25,if(AP25<>"",$A$1,"")) -> 44744.455 | AP25: done | AQ25: =if(AN25,if(AO25<>"",if(AO25>AN25,AO25-AN25,""),$A$1-AN25),"") -> 9.7907108 | AS25: =if(AJ25,if(and(hour(AJ25+AS$5)>11,(hour(AJ25+AS$5)<20)),AJ25+AS$5,_xlfn.workday.intl(int(AJ25),1,"1000000",Holidays!A:A)+hour(AJ25+AS$5-$B$1)/24+minute(AJ25)/1440),"") -> 44735.665 | AT25: =if(AT25,AT25,if(AU25<>"",$A$1,"")) -> 44744.455 | AU25: yes | AV25: =if(AS25,if(AT25<>"",if(AT25>AS25,AT25-AS25,""),$A$1-AS25),"") -> 8.7907506 | AX25: done
A26: 44636.498 | G26: =if(A26,_xlfn.workday.intl(int(A26),1,"1000000",Holidays!A:A)+17/24,"") -> 44637.708 | H26: =if(H26,H26,if(I26<>"",$A$1,"")) | J26: =if(G26,if(H26<>"",if(H26>G26,H26-G26,""),$A$1-G26),"") -> 1496.2756 | K26: =if(G26,_xlfn.workday.intl(int(G26),0,"1000000",Holidays!A:A)+19/24,"") -> 44637.792 | L26: =if(L26,L26,if(M26<>"",$A$1,"")) | N26: =if(K26,if(L26<>"",if(L26>K26,L26-K26,""),$A$1-K26),"") -> 1496.1922 | O26: =if(A26,_xlfn.WORKDAY.INTL(A26,O$5,"1000000",Holidays!A:A)+hour(A26)/24+MINUTE(A26)/1440,"") -> 44637.497 | R26: =if(O26,if(P26<>"",if(P26>O26,P26-O26,""),$A$1-O26),"") -> 1496.4867 | U26: =if(O26,_xlfn.WORKDAY.INTL(O26,U$5,"1000000",Holidays!A:A)+hour(O26)/24+MINUTE(O26)/1440,"") -> 44638.497 | V26: =if(V26,V26,if(W26<>"",$A$1,"")) | X26: =if(U26,if(V26<>"",if(V26>U26,V26-U26,""),$A$1-U26),"") -> 1495.4867 | AH26: =IF(P26="","",P26+AB26+AC26+AD26+AE26+AF26) | AI26: =if(AH26,_xlfn.workday.intl(int(AH26),0,"1000000",Holidays!A:A)+18/24,"") | AJ26: =if(AJ26,AJ26,if(AK26<>"",$A$1,"")) | AL26: =if(AI26,if(AJ26<>"",if(AJ26>AI26,AJ26-AI26,""),$A$1-AI26),"") | AN26: =if(AJ26,if(and(hour(AJ26+AN$5)>11,(hour(AJ26+AN$5)<20)),AJ26+AN$5,_xlfn.workday.intl(int(AJ26),1,"1000000",Holidays!A:A)+hour(AJ26+AN$5-$B$1)/24+minute(AJ26)/1440),"") | AO26: =if(AO26,AO26,if(AP26<>"",$A$1,"")) | AQ26: =if(AN26,if(AO26<>"",if(AO26>AN26,AO26-AN26,""),$A$1-AN26),"") | AS26: =if(AJ26,if(and(hour(AJ26+AS$5)>11,(hour(AJ26+AS$5)<20)),AJ26+AS$5,_xlfn.workday.intl(int(AJ26),1,"1000000",Holidays!A:A)+hour(AJ26+AS$5-$B$1)/24+minute(AJ26)/1440),"") | AT26: =if(AT26,AT26,if(AU26<>"",$A$1,"")) | AV26: =if(AS26,if(AT26<>"",if(AT26>AS26,AT26-AS26,""),$A$1-AS26),"") | AX26: No Response
A27: 44636.502 | G27: =if(A27,_xlfn.workday.intl(int(A27),1,"1000000",Holidays!A:A)+17/24,"") -> 44637.708 | H27: =if(H27,H27,if(I27<>"",$A$1,"")) | J27: =if(G27,if(H27<>"",if(H27>G27,H27-G27,""),$A$1-G27),"") -> 1496.2756 | K27: =if(G27,_xlfn.workday.intl(int(G27),0,"1000000",Holidays!A:A)+19/24,"") -> 44637.792 | L27: =if(L27,L27,if(M27<>"",$A$1,"")) | N27: =if(K27,if(L27<>"",if(L27>K27,L27-K27,""),$A$1-K27),"") -> 1496.1922 | O27: =if(A27,_xlfn.WORKDAY.INTL(A27,O$5,"1000000",Holidays!A:A)+hour(A27)/24+MINUTE(A27)/1440,"") -> 44637.501 | R27: =if(O27,if(P27<>"",if(P27>O27,P27-O27,""),$A$1-O27),"") -> 1496.4825 | U27: =if(O27,_xlfn.WORKDAY.INTL(O27,U$5,"1000000",Holidays!A:A)+hour(O27)/24+MINUTE(O27)/1440,"") -> 44638.501 | V27: =if(V27,V27,if(W27<>"",$A$1,"")) | X27: =if(U27,if(V27<>"",if(V27>U27,V27-U27,""),$A$1-U27),"") -> 1495.4825 | AB27: 2 | AH27: =IF(P27="","",P27+AB27+AC27+AD27+AE27+AF27) | AI27: =if(AH27,_xlfn.workday.intl(int(AH27),0,"1000000",Holidays!A:A)+18/24,"") | AJ27: =if(AJ27,AJ27,if(AK27<>"",$A$1,"")) | AL27: =if(AI27,if(AJ27<>"",if(AJ27>AI27,AJ27-AI27,""),$A$1-AI27),"") | AN27: =if(AJ27,if(and(hour(AJ27+AN$5)>11,(hour(AJ27+AN$5)<20)),AJ27+AN$5,_xlfn.workday.intl(int(AJ27),1,"1000000",Holidays!A:A)+hour(AJ27+AN$5-$B$1)/24+minute(AJ27)/1440),"") | AO27: =if(AO27,AO27,if(AP27<>"",$A$1,"")) | AQ27: =if(AN27,if(AO27<>"",if(AO27>AN27,AO27-AN27,""),$A$1-AN27),"") | AS27: =if(AJ27,if(and(hour(AJ27+AS$5)>11,(hour(AJ27+AS$5)<20)),AJ27+AS$5,_xlfn.workday.intl(int(AJ27),1,"1000000",Holidays!A:A)+hour(AJ27+AS$5-$B$1)/24+minute(AJ27)/1440),"") | AT27: =if(AT27,AT27,if(AU27<>"",$A$1,"")) | AV27: =if(AS27,if(AT27<>"",if(AT27>AS27,AT27-AS27,""),$A$1-AS27),"") | AX27: Hold
A28: 44636.509 | G28: =if(A28,_xlfn.workday.intl(int(A28),1,"1000000",Holidays!A:A)+17/24,"") -> 44637.708 | H28: =if(H28,H28,if(I28<>"",$A$1,"")) | J28: =if(G28,if(H28<>"",if(H28>G28,H28-G28,""),$A$1-G28),"") -> 1496.2756 | K28: =if(G28,_xlfn.workday.intl(int(G28),0,"1000000",Holidays!A:A)+19/24,"") -> 44637.792 | L28: =if(L28,L28,if(M28<>"",$A$1,"")) | N28: =if(K28,if(L28<>"",if(L28>K28,L28-K28,""),$A$1-K28),"") -> 1496.1922 | O28: =if(A28,_xlfn.WORKDAY.INTL(A28,O$5,"1000000",Holidays!A:A)+hour(A28)/24+MINUTE(A28)/1440,"") -> 44637.509 | R28: =if(O28,if(P28<>"",if(P28>O28,P28-O28,""),$A$1-O28),"") -> 1496.4749 | U28: =if(O28,_xlfn.WORKDAY.INTL(O28,U$5,"1000000",Holidays!A:A)+hour(O28)/24+MINUTE(O28)/1440,"") -> 44638.509 | V28: =if(V28,V28,if(W28<>"",$A$1,"")) | X28: =if(U28,if(V28<>"",if(V28>U28,V28-U28,""),$A$1-U28),"") -> 1495.4749 | AH28: =IF(P28="","",P28+AB28+AC28+AD28+AE28+AF28) | AI28: =if(AH28,_xlfn.workday.intl(int(AH28),0,"1000000",Holidays!A:A)+18/24,"") | AL28: =if(AI28,if(AJ28<>"",if(AJ28>AI28,AJ28-AI28,""),$A$1-AI28),"") | AN28: =if(AJ28,if(and(hour(AJ28+AN$5)>11,(hour(AJ28+AN$5)<20)),AJ28+AN$5,_xlfn.workday.intl(int(AJ28),1,"1000000",Holidays!A:A)+hour(AJ28+AN$5-$B$1)/24+minute(AJ28)/1440),"") | AO28: =if(AO28,AO28,if(AP28<>"",$A$1,"")) | AQ28: =if(AN28,if(AO28<>"",if(AO28>AN28,AO28-AN28,""),$A$1-AN28),"") | AS28: =if(AJ28,if(and(hour(AJ28+AS$5)>11,(hour(AJ28+AS$5)<20)),AJ28+AS$5,_xlfn.workday.intl(int(AJ28),1,"1000000",Holidays!A:A)+hour(AJ28+AS$5-$B$1)/24+minute(AJ28)/1440),"") | AT28: =if(AT28,AT28,if(AU28<>"",$A$1,"")) | AV28: =if(AS28,if(AT28<>"",if(AT28>AS28,AT28-AS28,""),$A$1-AS28),"") | AX28: Hold
