Workbook

Sheet FR1
A1: Timestamp | B1: Walk In Client Name | C1: Number | D1: No of People | E1: In Time | F1: Which Counter | G1: Attend By | H1: Items Seen | I1: If Not What were they looking for or why didn't they buy | J1: Kitty Explained/Give | K1: Out Time | L1: Gift Given | M1: Google Review Taken | N1: Insta Follow | O1: Communication | P1: Relation | Q1: Kitty Interested | R1: CLIENT TYPE | S1: Sale
A2: 45284.59 | B2: Om parkash | C2: 9811023449 | D2: 1 | E2: 0.097222222 | F2: Gold | G2: Bhumika | H2: Bangles | J2: Not interested | K2: 0.11597222 | L2: Yes | M2: Yes | N2: Not use | O2: CELLS | P2: Sir
A3: 45284.654 | B3: Sudhanshu | C3: 9610072943 | D3: 1 | E3: 0.10069444 | F3: Diamond | G3: Chhaya | H3: Chain with solitaire pendent | K3: 0.14583333 | L3: Yes | M3: Yes | N3: Not usr | O3: WA ONLY | P3: Sir
A4: 45284.655 | B4: Mukul | C4: 7042183683 | D4: 2 | E4: 0.25625 | F4: Gold | G4: Mansa,pooja | H4: Not sale | I4: Customer want gold bar not available this itme | J4: No | K4: 0.27083333 | L4: No | M4: No | N4: No | O4: WA ONLY | P4: Sir
A5: 45284.66 | B5: Benuji | C5: 9810668596 | D5: 1 | E5: 0.51736111 | F5: Diamond | G5: Sanjeev sir,chhaya, pooja | H5: CVD, tops, ring | J5: No | K5: 0.11458333 | L5: Yes | M5: Yes | N5: Not use insta | O5: WA ONLY, OWNER CONTACT ONLY | P5: Sir, Madam
A6: 45284.662 | B6: Shikha | C6: 8178148800 | D6: 3 | E6: 0.0625 | F6: Gold | G6: Reena, mansa | H6: Gold ring | K6: 0.086805556 | L6: Yes | N6: Yes | O6: WA ONLY | P6: Sir, Madam
A7: 45284.798 | B7: Tushar | C7: 9953450909 | D7: 2 | E7: 0.25 | F7: Gold | G7: Chhaya | H7: Gold gents ring | K7: 0.29861111 | L7: Yes | M7: Yes | N7: Yes | O7: WA ONLY, OWNER CONTACT ONLY | P7: Sir, Madam
A8: 45284.819 | B8: Tushar | C8: 9953450909 | D8: 2 | E8: 0.25 | F8: Gold | G8: Chhaya | H8: Gold ring | J8: Yes | K8: 0.3125 | L8: Yes | M8: Yes | N8: Yes | O8: WA ONLY, OWNER CONTACT ONLY | P8: Sir, Madam
A9: 45284.827 | B9: Atoshi | C9: 8700173741 | D9: 1 | E9: 0.25347222 | F9: Gold | G9: Mansa | H9: Gold ring,penden | J9: Yes | K9: 0.33333333 | L9: Yes | M9: Yes | N9: Yes | O9: WA ONLY, OWNER CONTACT ONLY | P9: Madam
A10: 45284.828 | B10: Afsana begam | C10: 9311691012 | D10: 1 | E10: 0.23958333 | F10: Gold | G10: Chhaya | H10: Ringyes | J10: Yes | K10: 0.3125 | L10: Yes | M10: Yes | N10: Not use | O10: WA ONLY | P10: Sir, Madam
A11: 45286.701 | B11: Sunita mehta | C11: 9810222843 | D11: 3 | E11: 0.11111111 | F11: Diamond | G11: Sanjeev sir,seema mam,reema | H11: Rapier Diamond ring | I11: Rapier Diamond ring | K11: 0.16666667 | L11: No | M11: Already done | N11: Already done | O11: WA ONLY | P11: Sir, Madam
A12: 45286.702 | B12: Amit kumar | C12: 9821489150 | D12: 1 | E12: 0.12847222 | F12: Gold | G12: Pooja | H12: Gold chain repair | K12: 0.12986111 | L12: No | O12: WA ONLY | P12: Sir, Madam
A13: 45286.703 | B13: Uttam | C13: 9810007503 | D13: 1 | E13: 0.12986111 | F13: Diamond | G13: Reema | H13: Repaire Diamond ring | K13: 0.13541667 | L13: Yes | M13: Already done | N13: Already done | O13: WA ONLY | P13: Sir
A14: 45286.706 | B14: Kritanjli | C14: 9873041853 | D14: 1 | E14: 0.16875 | F14: Antic | G14: Chhaya | H14: Gems gold ring( pic the order no concern person) | I14: no concern person | J14: no concern person | K14: 0.17708333 | L14: Yes | M14: no concern person | N14: no concern person | O14: WA ONLY | P14: Sir
A15: 45287.719 | B15: Pragya | C15: 9910603300 | D15: 1 | E15: 0.29513889 | F15: Diamond | G15: Reema | H15: Not sale any set because customer wont home and told which set he liked | K15: 0.34375 | L15: Yes | O15: WA ONLY | P15: Madam
A16: 45287.721 | B16: Raj karan | C16: 9560358448 | D16: 2 | E16: 0.19097222 | G16: Gold | H16: Customer wants Pendent but process in order | K16: 0.21875 | L16: Yes | M16: Yes | N16: Not use | O16: WA ONLY | P16: Sir, Madam
A17: 45287.772 | B17: Ravi | C17: 8882584436 | D17: 1 | E17: 0.24652778 | F17: Gold | G17: Mansa | H17: Silver anklet | J17: Not interested | K17: 0.27152778 | L17: No | M17: Already done | N17: Already done | O17: WA ONLY | P17: Sir
A18: 45287.803 | B18: Sumit | C18: 9212327770 | D18: 1 | E18: 0.28472222 | F18: Antic | G18: Chhaya | H18: Customer sel own gold coin 100 gm | K18: 0.29861111 | L18: Yes | O18: WA ONLY | P18: Sir
A19: 45288.67 | B19: Anu | C19: 9212674929 | D19: 1 | E19: 0.084027778 | F19: Gold | G19: Bhumika | H19: 2 pair tops | K19: 0.14583333 | L19: Yes | M19: Yes | N19: Not use | O19: WA ONLY | P19: Sir, Madam
A20: 45288.766 | B20: Veena rawal | C20: 8800939462 | D20: 1 | E20: 0.16944444 | F20: Antic | G20: Chhaya | H20: 100 gm gold bar | K20: 0.21875 | L20: Yes | M20: Yes | N20: Yes | O20: WA ONLY | P20: Madam
A21: 45288.783 | B21: Keshar | C21: 99999728283 | D21: 2 | E21: 0.19166667 | F21: Sntic | G21: Pooja | H21: Gold tops,mang tika | J21: Already done | K21: 0.27361111 | L21: Yes | M21: Yes | N21: Yes | O21: WA ONLY | P21: Sir, Madam
A22: 45288.784 | B22: Shilpi puri | C22: 9958950595 | D22: 2 | E22: 0.21041667 | F22: Diamond | G22: Reema | H22: Silver breslet but not sale because breslet not available in the store | K22: 0.22222222 | L22: No | O22: WA ONLY | P22: Madam
A23: 45288.801 | B23: Sharvan | C23: 7021183656 | D23: 1 | E23: 0.26597222 | F23: Gold | G23: Bhumika,mansa | H23: Gold mangal sutr | K23: 0.30208333 | L23: No | M23: Yes | N23: Yse | O23: WA ONLY | P23: Sir
A24: 45288.802 | B24: Mini | C24: 9818926253 | D24: 1 | E24: 0.19027778 | F24: Gold | G24: Bhumika,mansa | H24: Repairing | K24: 0.27291667 | L24: No | M24: Already done | N24: Already done | O24: WA ONLY | P24: Madam
A25: 45289.733 | B25: Shaista | C25: 8860741616 | D25: 1 | E25: 0.068055556 | F25: Gold | G25: Bhumika | H25: 2 pairs tops CVD | J25: Already done | K25: 0.18819444 | L25: Yes | M25: Already done | N25: Already done | O25: WA ONLY, OWNER CONTACT ONLY | P25: Madam
A26: 45289.738 | B26: Aissato guniea | C26: 622130284 | D26: 1 | E26: 0.083333333 | F26: Gold | G26: Bhumika | I26: To pair of chain selecte and ho to home discuss with family and visit in the store after 2 ya 3 days | J26: Not interested | K26: 0.14583333 | L26: Yes | M26: Feedback giving after Purchasing | N26: Noy use | O26: WA ONLY | P26: Madam
A27: 45289.742 | B27: Naresh | C27: 7011729202 | D27: 1 | E27: 0.15833333 | F27: Antic | G27: Chhaya | I27: Discuss with family and visit the store than purchase | J27: Not interested | K27: 0.20833333 | L27: Yes | M27: Customer give the feedback after purchasing | N27: Not use | O27: WA ONLY | P27: Sir
A28: 45289.749 | B28: Nikita | C28: 8860590814 | D28: 2 | E28: 0.20833333 | F28: Gold | G28: Chhaya mansa | I28: Customer will be discussed & visit store | K28: 0.22222222 | L28: Yes | O28: WA ONLY | P28: Sir, Madam
A29: 45289.751 | B29: Reha jain | C29: 8860590814 | D29: 2 | E29: 0.20833333 | F29: Diamond | G29: Reema | I29: 2 diamond ring order | K29: 0.24444444 | L29: No | M29: Yes | N29: Yes | O29: WA ONLY | P29: Sir, Madam
A30: 45289.789 | B30: Priya | C30: 9650745331 | D30: 3 | E30: 0.25069444 | F30: Diamond | G30: Reema | I30: Visit the store after 2 ya 3 days | J30: Already done | K30: 0.2875 | L30: Yes | M30: Already done | N30: Already done | O30: WA ONLY | P30: Madam
A31: 45290.535 | B31: Nada rku | C31: 8974251308 | D31: 1 | E31: 0.48958333 | F31: Diamond | G31: Reema | H31: Gems stone but | I31: One pendent order diamond and gold mix | J31: Not interested | K31: 0.53125 | L31: Yes | M31: Yes | N31: Yes | O31: WA ONLY | P31: Madam
A32: 45290.68 | B32: Urmil | C32: 9810775750 | D32: 2 | E32: 0.061111111 | F32: Antic | G32: Chhaya | I32: Kundan set remaking | J32: Next kitty batch will be customer start kitty | K32: 0.10416667 | L32: Yes | M32: Already done | N32: Already done | O32: WA ONLY | P32: Madam
A33: 45290.681 | B33: Satish yadav | C33: 92122710187 | D33: 1 | E33: 0.17083333 | F33: Gold | G33: Mansa, bhumika | I33: Tomorrow customer visit store with wife and want gold set | J33: Tomorrow come | K33: 0.17777778 | L33: Yes | M33: Tomorrow come | N33: Tomorrow come | O33: WA ONLY | P33: Sir
A34: 45290.773 | B34: Deepak | C34: 9811172888 | D34: 1 | E34: 0.12638889 | F34: Gold,antic | G34: Bhumika,chhaya pooja,msnsa | I34: Again visit | J34: Again visit | K34: 0.25902778 | L34: Yes | M34: After purchasing | N34: After purchasing | O34: WA ONLY, OWNER CONTACT ONLY | P34: Sir
A35: 45290.774 | B35: Om parkash | C35: 9811023449 | D35: 1 | E35: 0.24513889 | F35: Gold | I35: Balance full fill | J35: Not interested | K35: 0.25694444 | L35: Yes | M35: Already done | N35: Already done | O35: WA ONLY | P35: Sir
A36: 45290.781 | B36: Priyanka | C36: 9818668439 | D36: 2 | E36: 0.24513889 | F36: Antic | G36: Pooja,chhaya,seema mam | I36: Aging visit | K36: 0.27986111 | L36: Yes | M36: Again visit | N36: Not use | O36: WA ONLY, OWNER CONTACT ONLY | P36: Madam
A37: 45290.815 | B37: Atoshi | C37: 8700173741 | D37: 2 | E37: 0.29166667 | F37: Gold | G37: Bhumika,mansa | H37: Silver coin 20 gm | J37: Already done | K37: 0.31944444 | L37: Yes | M37: Already done | N37: Already done | O37: WA ONLY | P37: Madam
A38: 45291.693 | B38: Mini | C38: 9818926153 | D38: 1 | E38: 0.52638889 | F38: Gold | G38: Bhumika | I38: Repair diamond set | J38: Not interested | K38: 0.11111111 | L38: Yes | M38: Already done | N38: Already done | O38: WA ONLY | P38: Madam
A39: 45291.694 | B39: Ritu rathi | C39: 9818802720 | D39: 1 | E39: 0.060416667 | F39: Diamond | G39: Reena | I39: One diamond ring order | J39: Already taken | K39: 0.089583333 | L39: Yes | M39: Already done | N39: Already done | O39: WA ONLY, OWNER CONTACT ONLY | P39: Sir, Madam
A40: 45291.696 | B40: Vinita | C40: 9811488999 | D40: 2 | E40: 0.13611111 | F40: Gold | G40: Bhumika | I40: Polki set order | K40: 0.15902778 | L40: Yes | M40: Already done | N40: Already done | O40: WA ONLY, OWNER CONTACT ONLY | P40: Madam
...

Sheet old sheet data
A1: Timestamp | B1: Name | C1: Mobile | D1: Address | E1: Locality | F1: Your Birthday | G1: Your Anniversary | H1: Mail Id | I1: Reference Of | J1: Person Name
A2: 45205.477 | B2: saurav | C2: 9811464488 | D2: 2229, Sunsea, Hardhyan Singh Road, Karol Bagh | E2: Option 1
A3: 45212.663 | B3: Khushi | C3: 8506019383 | D3: Mzinejdhedbhxkk | E3: East | J3: Khushi
A4: 45213.541 | B4: Shah alam ji | C4: 9667903553 | D4: F-610A Sha complexes near bank of baroda | E4: North | F4: 19367 | J4: Chhaya
A5: 45214.583 | B5: Dr Shaista Khan | C5: 8860741616 | D5: T44/1, kalu sarai, hauz khas, new delhi 110016 | E5: South | F5: 45015 | G5: 45214 | H5: Shaistakhan343@yahoo.in | J5: Khushi
A6: 45214.585 | B6: Rita chaudhary | C6: 9868120901 | D6: G 41 spaze privy sector72gurgaon | E6: Gurgaon | F6: 45035 | H6: ritachaudhry19@gmail.com | J6: Khushi
A7: 45214.588 | B7: Rajbala | C7: 9582262162 | D7: 162, munirka, new delhi 110016 | E7: South | F7: 45292 | I7: Shaista khan | J7: Khushi
A8: 45214.588 | B8: Krishna rathi | C8: 9818294768 | D8: Munirka 222 | E8: South | I8: Shaista khan | J8: Khushi
A9: 45214.589 | B9: Rama gupta | C9: 7678373300 | D9: Sunder vihar | J9: Khushi
A10: 45214.589 | B10: Shilpa gupta | C10: 8447442044 | D10: Rohini east | E10: East | F10: 26261 | G10: 33711 | J10: Lipi
A11: 45214.594 | B11: Niharika | C11: 9419877098 | D11: Jammu | E11: Outstation | G11: 43498 | I11: Seema ma'am | J11: Harsha
A12: 45214.595 | B12: Chetan patel | C12: 7383344655 | D12: Delhi | E12: South | I12: Seema ma'am | J12: Harsha
A13: 45214.602 | B13: Surendra gupta | C13: 9810190708 | D13: C 181 vivek vihar delhi 110095 | E13: East | F13: 45050 | H13: gupta2019surendra@gmail.com | I13: Sanjeev garg | J13: Khushi
A14: 45214.609 | B14: Richa chaudhry | C14: 9810483570 | D14: G-1, 42 spaze privi sector-72 gurgao | E14: Gurgaon | J14: Khushi
A15: 45214.617 | B15: Arvind kumar gupta | C15: 9810403852 | D15: B-245 ramprastha colony gaziabad | E15: Outstation | J15: Khushi
A16: 45214.638 | B16: Sandhya gupta | C16: 8800699054 | D16: C-181 vivek vihar | J16: Khushi
A17: 45214.667 | B17: Rashi jain | C17: 8510007279 | D17: New delhi | J17: Khushi
A18: 45214.679 | B18: Nimishagupta | C18: 9811088872 | D18: G320 preet vihar | E18: East | F18: 45145 | G18: 45061 | I18: Sanjeev garg | J18: priya
A19: 45214.69 | B19: Sudesh jain | C19: 9811263840 | D19: A-114, upperground floor, saraswati vihar, delhi 110034 | E19: North | F19: 45203 | J19: Khushi
A20: 45214.691 | B20: bhavana vadudeva | C20: 9810042634 | D20: 7c pocket 12 vaishali apartments kalkaji extdion new delhi19 | E20: East | F20: 45020 | G20: 45215 | I20: saurav garg | J20: Priya pc
A21: 45214.712 | B21: Soniya gupta | C21: 9599223396 | D21: D for Delhi 133 sorajval bihar | E21: East | F21: 45209 | J21: Priya pc
A22: 45214.72 | B22: prial | C22: 9910925269 | D22: 149 sector 14 faridabad | E22: East | I22: upasna bhandari | J22: priya
A23: 45214.724 | B23: Yatin jain | C23: 9811233455 | D23: BA-36 west shalimar bagh new delhi-88 | E23: North | F23: 33114 | G23: 43936 | H23: Yatin@jaincogroup.com | I23: Tuti garg | J23: Khushi
A24: 45214.725 | B24: Ritu jain | C24: 9582808468 | D24: 67/3 zamrudpur g. K part 1 | J24: priya pc
A25: 45215.566 | B25: pankaj bansal | C25: 9911014950 | D25: b49 east jyoti nagar | E25: East | I25: sanjeev garg | J25: Priya pc
A26: 45215.57 | B26: Rohini | C26: 9990014950 | D26: Jyoti nagar | J26: priya pc
A27: 45215.572 | B27: Jl ahuja | C27: 9818017921 | D27: L 74 ground floor kirti nagar | J27: priya pc
A28: 45215.573 | B28: Shashi ahuja | C28: 9811108266 | D28: L 74 kirti nagar | H28: Jla80shashi @hotmail.com | I28: Jl ahuja | J28: Khushi
A29: 45215.574 | B29: Kavita kapila | C29: 9015802726 | D29: 57 a ua jawahar nagar 3 rd floor | J29: Khushi
A30: 45215.574 | B30: Khushboo kapila | C30: 9891567166 | D30: Jawahar nagar | I30: Kavita kapila | J30: Khushi
A31: 45215.587 | B31: Aastha | C31: 7011435956 | D31: Dlf moti nagar | J31: Khushi
A32: 45215.61 | B32: Santosh | C32: 9212157824 | D32: 5925/4gali no. 1 devnagar karol bagh | E32: Central | F32: 27139 | J32: Khushi
A33: 45215.611 | B33: Kusum singh | C33: 8368953488 | D33: T 47 ratan nagar karol bagh | J33: priya pc
A34: 45215.611 | B34: Atoshi singh | C34: 8700173441 | D34: Karol bagh | J34: priya pc
A35: 45215.612 | B35: Himanshu | C35: 8368329315 | D35: Dev nagar karolbagh | E35: Central | F35: 45205 | H35: Hc278368@gmailcom | J35: Khushi
A36: 45215.614 | B36: Ritu rathi | C36: 9818802720 | D36: Dlf moti nagar | J36: Khushi
A37: 45215.649 | B37: vanshika | C37: 9069461111 | D37: b 2101 painiyar park secter 61 gudgao | F37: 45219 | J37: Priya pc
A38: 45215.749 | B38: Mukesh mehta | C38: 9312401235 | D38: 2695 mukherjee nagar | J38: Khushi
A39: 45215.75 | B39: Ishaan | C39: 9312401235 | D39: Mukherjee nagar | I39: Mukesh mehta | J39: Khushi
A40: 45215.76 | B40: Mwaka | C40: 9821166531 | D40: J 197 gamma 2 greater noida | H40: Mnynamukonda@gmail.com | J40: Khushi
...

Sheet Data Paste
A1: Timestamp | B1: Walk In Client Name | C1: Number | D1: No of People | E1: In Time | F1: Which Counter | G1: Attend By | H1: Items Seen | I1: If Not What were they looking for or why didn't they buy | J1: Kitty Explained/Give | K1: Out Time | L1: Gift Given | M1: Google Review Taken | N1: Insta Follow | O1: Communication | P1: Relation | Q1: Kitty Interested | R1: CLIENT TYPE | S1: Sale
A2: 45736.784 | B2: Atoshi | C2: 8700173741 | D2: 1 | E2: 0.25347222 | F2: Gold | G2: Deepali | H2: Gold ring,penden | J2: Yes | K2: 0.33333333 | L2: Yes | M2: Yes | N2: Yes | O2: WA ONLY, OWNER CONTACT ONLY | P2: Madam
A3: 45736.787 | B3: Afsana begam | C3: 9311691012 | D3: 1 | E3: 0.23958333 | F3: Gold | G3: Deepali | H3: Ringyes | J3: Yes | K3: 0.3125 | L3: Yes | M3: Yes | N3: Not use | O3: WA ONLY | P3: Sir, Madam
A4: 45736.788 | B4: Amit kumar | C4: 9821489150 | D4: 1 | E4: 0.12847222 | F4: Gold | G4: Deepali | H4: Gold chain repair | K4: 0.12986111 | L4: No | O4: WA ONLY | P4: Sir, Madam
A5: 45736.789 | B5: Uttam | C5: 9810007503 | D5: 1 | E5: 0.12986111 | F5: Diamond | G5: Deepali | H5: Repaire Diamond ring | K5: 0.13541667 | L5: Yes | M5: Already done | N5: Already done | O5: WA ONLY | P5: Sir
A6: 45736.79 | B6: Kritanjli | C6: 9873041853 | D6: 1 | E6: 0.16875 | F6: Antic | G6: Deepali | H6: Gems gold ring( pic the order no concern person) | I6: no concern person | J6: no concern person | K6: 0.17708333 | L6: Yes | M6: no concern person | N6: no concern person | O6: WA ONLY | P6: Sir
A7: 45736.791 | B7: Pragya | C7: 9910603300 | D7: 1 | E7: 0.29513889 | F7: Diamond | G7: Deepali | H7: Not sale any set because customer wont home and told which set he liked | K7: 0.34375 | L7: Yes | O7: WA ONLY | P7: Madam
A8: 45736.797 | B8: Raj karan | C8: 9560358448 | D8: 2 | E8: 0.19097222 | G8: Deepali | H8: Customer wants Pendent but process in order | K8: 0.21875 | L8: Yes | M8: Yes | N8: Not use | O8: WA ONLY | P8: Sir, Madam
A9: 45736.813 | B9: Ravi | C9: 8882584436 | D9: 1 | E9: 0.24652778 | F9: Gold | G9: Deepali | H9: Silver anklet | J9: Not interested | K9: 0.27152778 | L9: No | M9: Already done | N9: Already done | O9: WA ONLY | P9: Sir
A10: 45736.814 | B10: Sumit | C10: 9212327770 | D10: 1 | E10: 0.28472222 | F10: Antic | G10: Deepali | H10: Customer sel own gold coin 100 gm | K10: 0.29861111 | L10: Yes | O10: WA ONLY | P10: Sir
A11: 45736.815 | B11: Anu | C11: 9212674929 | D11: 1 | E11: 0.084027778 | F11: Gold | G11: Deepali | H11: 2 pair tops | K11: 0.14583333 | L11: Yes | M11: Yes | N11: Not use | O11: WA ONLY | P11: Sir, Madam
A12: 45736.815 | B12: Keshar | C12: 99999728283 | D12: 2 | E12: 0.19166667 | F12: Sntic | G12: Deepali | H12: Gold tops,mang tika | J12: Already done | K12: 0.27361111 | L12: Yes | M12: Yes | N12: Yes | O12: WA ONLY | P12: Sir, Madam
A13: 45734.75 | B13: Om parkash | C13: 9811023449 | D13: 1 | E13: 0.097222222 | F13: Gold | G13: Deepali | H13: Bangles | J13: Not interested | K13: 0.11597222 | L13: Yes | M13: Yes | N13: Not use | O13: CELLS | P13: Sir
A14: 45734.767 | B14: Sudhanshu | C14: 9610072943 | D14: 1 | E14: 0.10069444 | F14: Diamond | G14: Deepali | H14: Chain with solitaire pendent | K14: 0.14583333 | L14: Yes | M14: Yes | N14: Not usr | O14: WA ONLY | P14: Sir
A15: 45734.771 | B15: Mukul | C15: 7042183683 | D15: 2 | E15: 0.25625 | F15: Gold | G15: Deepali | H15: Not sale | I15: Customer want gold bar not available this itme | J15: No | K15: 0.27083333 | L15: No | M15: No | N15: No | O15: WA ONLY | P15: Sir
A16: 45734.774 | B16: Benuji | C16: 9810668596 | D16: 1 | E16: 0.51736111 | F16: Diamond | G16: Deepali | H16: CVD, tops, ring | J16: No | K16: 0.11458333 | L16: Yes | M16: Yes | N16: Not use insta | O16: WA ONLY, OWNER CONTACT ONLY | P16: Sir, Madam
A17: 45734.778 | B17: Shikha | C17: 8178148800 | D17: 3 | E17: 0.0625 | F17: Gold | G17: Deepali | H17: Gold ring | K17: 0.086805556 | L17: Yes | N17: Yes | O17: WA ONLY | P17: Sir, Madam
A18: 45734.781 | B18: Tushar | C18: 9953450909 | D18: 2 | E18: 0.25 | F18: Gold | G18: Sapna | H18: Gold gents ring | K18: 0.29861111 | L18: Yes | M18: Yes | N18: Yes | O18: WA ONLY, OWNER CONTACT ONLY | P18: Sir, Madam
A19: 45737.641 | B19: Parmod | C19: 9891143023 | D19: 2 | E19: 0.10416667 | F19: Diamond | G19: Preeti | I19: Discuss with family | J19: Discuss with family | K19: 0.13888889 | L19: Yes | M19: No after purchase | N19: No after purchase | O19: WA ONLY | P19: Sir, Madam
A20: 45737.645 | B20: Alifiya | C20: 7838408250 | D20: 6 | E20: 0.31111111 | F20: gold | G20: Sapna | I20: Customer not satisfied gold ring design | J20: Not interested | K20: 0.31736111 | L20: Yes | M20: No after purchase | N20: No after purchase | O20: WA ONLY | P20: Sir, Madam
A21: 45737.647 | B21: Ankush sharma | C21: 9817922929 | D21: 1 | E21: 0.082638889 | F21: Diamond | G21: Preeti | I21: Confirm diamond rate with kerot | J21: Not interested | K21: 0.084722222 | L21: Yes | M21: No | N21: No | O21: WA ONLY | P21: Sir
A22: 45737.647 | B22: Anita | C22: 8010046101 | D22: 2 | E22: 0.11666667 | F22: Antic | G22: Suman | I22: Done the payment | J22: Not interested | K22: 0.13541667 | L22: Yes | M22: Already done | N22: Already done | O22: WA ONLY | P22: Sir, Madam
A23: 45737.647 | B23: Rajeev gera | C23: 9990145453 | D23: 1 | E23: 0.12222222 | F23: Gold | G23: Sapna | H23: Antic gold set | J23: Not interested | K23: 0.20972222 | L23: Yes | M23: Already done | N23: Already done | O23: WA ONLY, OWNER CONTACT ONLY | P23: Sir, Madam
A24: 45737.649 | B24: Saloni | C24: 8287645704 | D24: 1 | E24: 0.14027778 | F24: Diamond | G24: Preeti | I24: Visit again with family | J24: Visit again with family | K24: 0.16319444 | L24: Yes | M24: After purchase | N24: After purchase | O24: WA ONLY | P24: Madam
A25: 45737.651 | B25: Monika | C25: 7300620421 | D25: 1 | E25: 0.05 | F25: Antic | G25: Suman | I25: Visit again | J25: Not interested | K25: 0.0625 | L25: Yes | M25: Already done | N25: Already done | O25: WA ONLY | P25: Madam
A26: 45737.652 | B26: Atoshi | C26: 8700173741 | D26: 1 | E26: 0.17986111 | F26: Antic | G26: Suman | I26: Payment done and oder | J26: Not interested | K26: 0.20694444 | L26: Yes | M26: Already done | N26: Already done | O26: WA ONLY | P26: Madam
A27: 45737.652 | B27: Naidu | C27: 9717611464 | D27: 2 | E27: 0.25 | F27: Antic | G27: Deepali | H27: Gold kids earing | J27: Not interested | K27: 0.30416667 | L27: Yes | M27: Yes | N27: Yes | O27: WA ONLY | P27: Sir, Madam
A28: 45737.653 | B28: Priyal | C28: 9910925269 | D28: 1 | E28: 0.29166667 | F28: Diamond | G28: Preeti | H28: Two breslet diamond | J28: Not interested | K28: 0.36319444 | L28: Yes | M28: Already done | N28: Already done | O28: WA ONLY | P28: Sir, Madam
A29: 45737.653 | B29: Dr. Mehta | C29: 9310857548 | D29: 1 | E29: 0.52708333 | F29: Diamond | G29: Preeti | I29: 2 diamond set approval | J29: Not interested | M29: Already done | N29: Already done | O29: WA ONLY | P29: Sir
A30: 45737.658 | B30: Shivani manchanda | C30: 9560341110 | D30: 1 | E30: 0.049305556 | F30: Antic | G30: Suman | I30: Pic the order | K30: 0.075 | L30: Yes | M30: Already done | N30: Already done | O30: WA ONLY | P30: Madam
A31: 45737.658 | B31: Bharti | C31: 9873833656 | D31: 1 | E31: 0.0625 | F31: Gold | G31: Sapna | H31: Gaems stone | J31: Not interested | K31: 0.071527778 | L31: Yes | M31: Already done | N31: Already done | O31: WA ONLY | P31: Madam
A32: 45737.658 | B32: P.d sharma | C32: 9971097482 | D32: 1 | E32: 0.092361111 | F32: Gold | G32: Sapna | I32: Customer not satisfied gold Bali making charges | J32: Not interested | K32: 0.095833333 | L32: Yes | M32: No | N32: No | O32: WA ONLY | P32: Sir, Madam
A33: 45737.66 | B33: Tahir | C33: 6205203880 | D33: 1 | E33: 0.092361111 | F33: Gold | G33: Sapna | H33: Gold chain | J33: Not interested | K33: 0.16805556 | L33: Yes | M33: Yes | N33: Yes | O33: WA ONLY | P33: Sir, Madam
A34: 45737.66 | B34: R.k tiwari | C34: 9555152166 | D34: 1 | E34: 0.14375 | F34: Gold | G34: Sapna | I34: Customer not satisfied with hold jhumki design | J34: Not interested | K34: 0.15972222 | L34: Yes | M34: No | N34: No | O34: WA ONLY | P34: Sir, Madam
A35: 45738.575 | B35: Gurman Singh | C35: 9899226225 | D35: 1 | E35: 0.10277778 | F35: Diamond | G35: Preeti | H35: Diamond pendent set | J35: Not interested | K35: 0.16041667 | L35: Yes | M35: Already done | N35: Already done | O35: WA ONLY | P35: Sir
A36: 45738.578 | B36: Mehek dhawan | C36: 9999678088 | D36: 2 | E36: 0.22916667 | F36: Antic | G36: Suman | I36: Customer discuss with family and visit again | J36: Not interested | K36: 0.26458333 | L36: Yes | M36: No | N36: No | O36: WA ONLY | P36: Sir, Madam
A37: 45738.611 | B37: Anil Choudhary | C37: 9811456708 | D37: 1 | E37: 0.29305556 | F37: Gold | G37: Sapna | I37: Visit again | J37: Visit again | K37: 0.29791667 | L37: Yes | M37: No | N37: No | O37: WA ONLY | P37: Sir, Madam
A38: 45738.615 | B38: Gurmeet | C38: 9971052404 | D38: 1 | E38: 0.14236111 | F38: Gold,diamond | G38: Sapna | H38: Silver ganesh and Laxmi murti | J38: Not interested | K38: 0.19097222 | L38: Yes | M38: Yes | N38: Not use | O38: WA ONLY | P38: Sir, Madam
A39: 45738.618 | B39: Shushil kumar | C39: 9971389387 | D39: 1 | E39: 0.17708333 | F39: Antic | G39: Suman | I39: Advance payment done | J39: Not interested | K39: 0.23333333 | L39: Yes | M39: Already done | N39: Already done | O39: WA ONLY | P39: Sir, Madam
A40: 45738.618 | B40: Shushil kumar | C40: 9971389387 | D40: 1 | E40: 0.17708333 | F40: Antic | G40: Suman | I40: Advance payment done | J40: Not interested | K40: 0.23333333 | L40: Yes | M40: Already done | N40: Already done | O40: WA ONLY | P40: Sir, Madam
...

Sheet Sales yes
A1: How many Days | B1: Message
A2: 0 | B2: Name ji, Wholeheartdly thank you for your trust and making a purchase today with us. We welcome you to Sun Sea Family, Your Wedding Jewellery Specialist. | C2: Thank You
A3: 8 | B3: This offer is between you and me | C3: Overview of Services - Highlight custom designs, repairs, and other services.
A4: 15 | C4: Feedback Request - Encourage feedback on their shopping experience.
A5: 22 | C5: Offer Announcement - Share a special offer for WhatsApp subscribers.
A6: 29 | C6: Loyalty Program Introduction - Invite clients to join your loyalty program.
A7: 36 | C7: Jewelry Care Tips - Educate clients on maintaining their jewelry.
A8: 43 | C8: Monthly Gold Rate Update - Keep clients informed about the market.
A9: 50 | C9: Styling Tips - Share advice on styling jewelry for different occasions.
A10: 57 | C10: Share a positive customer testimonial to build trust and credibility.
A11: 64 | C11: Highlight new arrivals or trending collections.
A12: 71 | C12: Introduce the Kitty Scheme - Encourage clients to enroll.
A13: 78 | C13: Special Promotion - Announce an exclusive discount or event for members.
A14: 85 | C14: Poll or Question - Engage clients with interactive content.
A15: 92 | C15: Behind-the-Scenes Look - Give insight into the jewelry-making process.
... A17: 106 | C17: Final Message - Recap of engagement, invite feedback, and encourage future store visits.
C18: Monthly Gold Rate Updates: First Monday of each month.
C19: Quarterly Newsletter: Include updates, offers, testimonials, and invitations to store events.

Sheet Sales no
A1: How many Days | B1: Message

Sheet Print
A1: S No | B1: {='FR1'!A1:P1} -> Timestamp | C1: Walk In Client Name | D1: Number | E1: No of People | F1: In Time | G1: Which Counter | H1: Attend By | I1: Items Seen | J1: If Not What were they looking for or why didn't they buy | K1: Kitty Explained/Give | L1: Out Time | M1: Gift Given | N1: Google Review Taken | O1: Insta Follow | P1: Communication | Q1: Relation | R1: Kitty Interested | S1: Client type | T1: Client type
A14: {=if(B14:B1013<>"",ROW(B14:B1013)-1,"")}

Sheet Sheet3

Sheet OUTPUT
A1: {=UNIQUE('FR1'!C:C)} -> Number | B1: FREQUENCY | C1: NAME | D1: TIME | E1: SALE STATUS
A2: 9811023449 | B2: =COUNTIF('FR1'!C:C, A2) -> 2 | C2: {=INDEX('FR1'!B:B, MATCH(A2, 'FR1'!C:C, 0))} -> Om parkash | D2: {=INDEX('FR1'!A:A, MATCH(A2, 'FR1'!C:C, 0))} -> 45284.59 | E2: {=IF(ISBLANK(INDEX('FR1'!H:H, MATCH(A2, 'FR1'!C:C, 0))), "LEAD OPEN", INDEX('FR1'!H:H, MATCH(A2, 'FR1'!C:C, 0)))} -> Bangles | F2: =IF(ISBLANK(INDEX(FR1!F2:R1000, MATCH(A2, FR1!C:C, 0), 1)), "No additional data", INDEX(FR1!F2:R1000, MATCH(A2, FR1!C:C, 0), 1)) // Adjust the range to cover your data -> #ERROR!
A3: 9610072943 | B3: =COUNTIF('FR1'!C:C, A3) -> 1 | C3: {=INDEX('FR1'!B:B, MATCH(A3, 'FR1'!C:C, 0))} -> Sudhanshu | D3: {=INDEX('FR1'!A:A, MATCH(A3, 'FR1'!C:C, 0))} -> 45284.654 | E3: {=IF(ISBLANK(INDEX('FR1'!H:H, MATCH(A3, 'FR1'!C:C, 0))), "LEAD OPEN", INDEX('FR1'!H:H, MATCH(A3, 'FR1'!C:C, 0)))} -> Chain with solitaire pendent
A4: 7042183683 | B4: =COUNTIF('FR1'!C:C, A4) -> 1 | C4: {=INDEX('FR1'!B:B, MATCH(A4, 'FR1'!C:C, 0))} -> Mukul | D4: {=INDEX('FR1'!A:A, MATCH(A4, 'FR1'!C:C, 0))} -> 45284.655 | E4: {=IF(ISBLANK(INDEX('FR1'!H:H, MATCH(A4, 'FR1'!C:C, 0))), "LEAD OPEN", INDEX('FR1'!H:H, MATCH(A4, 'FR1'!C:C, 0)))} -> Not sale
A5: 9810668596 | B5: =COUNTIF('FR1'!C:C, A5) -> 1 | C5: {=INDEX('FR1'!B:B, MATCH(A5, 'FR1'!C:C, 0))} -> Benuji | D5: {=INDEX('FR1'!A:A, MATCH(A5, 'FR1'!C:C, 0))} -> 45284.66 | E5: {=IF(ISBLANK(INDEX('FR1'!H:H, MATCH(A5, 'FR1'!C:C, 0))), "LEAD OPEN", INDEX('FR1'!H:H, MATCH(A5, 'FR1'!C:C, 0)))} -> CVD, tops, ring
A6: 8178148800 | B6: =COUNTIF('FR1'!C:C, A6) -> 3 | C6: {=INDEX('FR1'!B:B, MATCH(A6, 'FR1'!C:C, 0))} -> Shikha | D6: {=INDEX('FR1'!A:A, MATCH(A6, 'FR1'!C:C, 0))} -> 45284.662 | E6: {=IF(ISBLANK(INDEX('FR1'!H:H, MATCH(A6, 'FR1'!C:C, 0))), "LEAD OPEN", INDEX('FR1'!H:H, MATCH(A6, 'FR1'!C:C, 0)))} -> Gold ring
A7: 9953450909 | B7: =COUNTIF('FR1'!C:C, A7) -> 3 | C7: {=INDEX('FR1'!B:B, MATCH(A7, 'FR1'!C:C, 0))} -> Tushar | D7: {=INDEX('FR1'!A:A, MATCH(A7, 'FR1'!C:C, 0))} -> 45284.798 | E7: {=IF(ISBLANK(INDEX('FR1'!H:H, MATCH(A7, 'FR1'!C:C, 0))), "LEAD OPEN", INDEX('FR1'!H:H, MATCH(A7, 'FR1'!C:C, 0)))} -> Gold gents ring
A8: 8700173741 | B8: =COUNTIF('FR1'!C:C, A8) -> 11 | C8: {=INDEX('FR1'!B:B, MATCH(A8, 'FR1'!C:C, 0))} -> Atoshi | D8: {=INDEX('FR1'!A:A, MATCH(A8, 'FR1'!C:C, 0))} -> 45284.827 | E8: {=IF(ISBLANK(INDEX('FR1'!H:H, MATCH(A8, 'FR1'!C:C, 0))), "LEAD OPEN", INDEX('FR1'!H:H, MATCH(A8, 'FR1'!C:C, 0)))} -> Gold ring,penden
A9: 9311691012 | B9: =COUNTIF('FR1'!C:C, A9) -> 4 | C9: {=INDEX('FR1'!B:B, MATCH(A9, 'FR1'!C:C, 0))} -> Afsana begam | D9: {=INDEX('FR1'!A:A, MATCH(A9, 'FR1'!C:C, 0))} -> 45284.828 | E9: {=IF(ISBLANK(INDEX('FR1'!H:H, MATCH(A9, 'FR1'!C:C, 0))), "LEAD OPEN", INDEX('FR1'!H:H, MATCH(A9, 'FR1'!C:C, 0)))} -> Ringyes
A10: 9810222843 | B10: =COUNTIF('FR1'!C:C, A10) -> 1 | C10: {=INDEX('FR1'!B:B, MATCH(A10, 'FR1'!C:C, 0))} -> Sunita mehta | D10: {=INDEX('FR1'!A:A, MATCH(A10, 'FR1'!C:C, 0))} -> 45286.701 | E10: {=IF(ISBLANK(INDEX('FR1'!H:H, MATCH(A10, 'FR1'!C:C, 0))), "LEAD OPEN", INDEX('FR1'!H:H, MATCH(A10, 'FR1'!C:C, 0)))} -> Rapier Diamond ring
A11: 9821489150 | B11: =COUNTIF('FR1'!C:C, A11) -> 1 | C11: {=INDEX('FR1'!B:B, MATCH(A11, 'FR1'!C:C, 0))} -> Amit kumar | D11: {=INDEX('FR1'!A:A, MATCH(A11, 'FR1'!C:C, 0))} -> 45286.702 | E11: {=IF(ISBLANK(INDEX('FR1'!H:H, MATCH(A11, 'FR1'!C:C, 0))), "LEAD OPEN", INDEX('FR1'!H:H, MATCH(A11, 'FR1'!C:C, 0)))} -> Gold chain repair
A12: 9810007503 | B12: =COUNTIF('FR1'!C:C, A12) -> 2 | C12: {=INDEX('FR1'!B:B, MATCH(A12, 'FR1'!C:C, 0))} -> Uttam | D12: {=INDEX('FR1'!A:A, MATCH(A12, 'FR1'!C:C, 0))} -> 45286.703 | E12: {=IF(ISBLANK(INDEX('FR1'!H:H, MATCH(A12, 'FR1'!C:C, 0))), "LEAD OPEN", INDEX('FR1'!H:H, MATCH(A12, 'FR1'!C:C, 0)))} -> Repaire Diamond ring
A13: 9873041853 | B13: =COUNTIF('FR1'!C:C, A13) -> 5 | C13: {=INDEX('FR1'!B:B, MATCH(A13, 'FR1'!C:C, 0))} -> Kritanjli | D13: {=INDEX('FR1'!A:A, MATCH(A13, 'FR1'!C:C, 0))} -> 45286.706 | E13: {=IF(ISBLANK(INDEX('FR1'!H:H, MATCH(A13, 'FR1'!C:C, 0))), "LEAD OPEN", INDEX('FR1'!H:H, MATCH(A13, 'FR1'!C:C, 0)))} -> Gems gold ring( pic the order no concern person)
A14: 9910603300 | B14: =COUNTIF('FR1'!C:C, A14) -> 1 | C14: {=INDEX('FR1'!B:B, MATCH(A14, 'FR1'!C:C, 0))} -> Pragya | D14: {=INDEX('FR1'!A:A, MATCH(A14, 'FR1'!C:C, 0))} -> 45287.719 | E14: {=IF(ISBLANK(INDEX('FR1'!H:H, MATCH(A14, 'FR1'!C:C, 0))), "LEAD OPEN", INDEX('FR1'!H:H, MATCH(A14, 'FR1'!C:C, 0)))} -> Not sale any set because customer wont home and told which set he liked
... A52: 9868120901 | B52: =COUNTIF('FR1'!C:C, A52) -> 1 | C52: {=INDEX('FR1'!B:B, MATCH(A52, 'FR1'!C:C, 0))} -> Ritu Choudhary | D52: {=INDEX('FR1'!A:A, MATCH(A52, 'FR1'!C:C, 0))} -> 45298.76 | E52: {=IF(ISBLANK(INDEX('FR1'!H:H, MATCH(A52, 'FR1'!C:C, 0))), "LEAD OPEN", INDEX('FR1'!H:H, MATCH(A52, 'FR1'!C:C, 0)))} -> Gold chain
B53: =COUNTIF('FR1'!C:C, A53) -> 0 | C53: {=INDEX('FR1'!B:B, MATCH(A53, 'FR1'!C:C, 0))} -> #N/A | D53: {=INDEX('FR1'!A:A, MATCH(A53, 'FR1'!C:C, 0))} -> #N/A | E53: {=IF(ISBLANK(INDEX('FR1'!H:H, MATCH(A53, 'FR1'!C:C, 0))), "LEAD OPEN", INDEX('FR1'!H:H, MATCH(A53, 'FR1'!C:C, 0)))} -> #N/A
A54: 9525203641 | B54: =COUNTIF('FR1'!C:C, A54) -> 1 | C54: {=INDEX('FR1'!B:B, MATCH(A54, 'FR1'!C:C, 0))} -> MD salehin | D54: {=INDEX('FR1'!A:A, MATCH(A54, 'FR1'!C:C, 0))} -> 45298.765 | E54: {=IF(ISBLANK(INDEX('FR1'!H:H, MATCH(A54, 'FR1'!C:C, 0))), "LEAD OPEN", INDEX('FR1'!H:H, MATCH(A54, 'FR1'!C:C, 0)))} -> Gold ring
A55: 9999507907 | B55: =COUNTIF('FR1'!C:C, A55) -> 1 | C55: {=INDEX('FR1'!B:B, MATCH(A55, 'FR1'!C:C, 0))} -> Gorav | D55: {=INDEX('FR1'!A:A, MATCH(A55, 'FR1'!C:C, 0))} -> 45298.766 | E55: {=IF(ISBLANK(INDEX('FR1'!H:H, MATCH(A55, 'FR1'!C:C, 0))), "LEAD OPEN", INDEX('FR1'!H:H, MATCH(A55, 'FR1'!C:C, 0)))} -> LEAD OPEN
A56: 9643705979 | B56: =COUNTIF('FR1'!C:C, A56) -> 3 | C56: {=INDEX('FR1'!B:B, MATCH(A56, 'FR1'!C:C, 0))} -> Manjeet | D56: {=INDEX('FR1'!A:A, MATCH(A56, 'FR1'!C:C, 0))} -> 45298.774 | E56: {=IF(ISBLANK(INDEX('FR1'!H:H, MATCH(A56, 'FR1'!C:C, 0))), "LEAD OPEN", INDEX('FR1'!H:H, MATCH(A56, 'FR1'!C:C, 0)))} -> LEAD OPEN
A57: 9312229038 | B57: =COUNTIF('FR1'!C:C, A57) -> 1 | C57: {=INDEX('FR1'!B:B, MATCH(A57, 'FR1'!C:C, 0))} -> Neena | D57: {=INDEX('FR1'!A:A, MATCH(A57, 'FR1'!C:C, 0))} -> 45298.803 | E57: {=IF(ISBLANK(INDEX('FR1'!H:H, MATCH(A57, 'FR1'!C:C, 0))), "LEAD OPEN", INDEX('FR1'!H:H, MATCH(A57, 'FR1'!C:C, 0)))} -> Gokd pendent
A58: 9886328522 | B58: =COUNTIF('FR1'!C:C, A58) -> 1 | C58: {=INDEX('FR1'!B:B, MATCH(A58, 'FR1'!C:C, 0))} -> Ina | D58: {=INDEX('FR1'!A:A, MATCH(A58, 'FR1'!C:C, 0))} -> 45298.822 | E58: {=IF(ISBLANK(INDEX('FR1'!H:H, MATCH(A58, 'FR1'!C:C, 0))), "LEAD OPEN", INDEX('FR1'!H:H, MATCH(A58, 'FR1'!C:C, 0)))} -> Ina
A59: 9654141505 | B59: =COUNTIF('FR1'!C:C, A59) -> 4 | C59: {=INDEX('FR1'!B:B, MATCH(A59, 'FR1'!C:C, 0))} -> Sagar | D59: {=INDEX('FR1'!A:A, MATCH(A59, 'FR1'!C:C, 0))} -> 45298.825 | E59: {=IF(ISBLANK(INDEX('FR1'!H:H, MATCH(A59, 'FR1'!C:C, 0))), "LEAD OPEN", INDEX('FR1'!H:H, MATCH(A59, 'FR1'!C:C, 0)))} -> LEAD OPEN
A60: 9818802702 | B60: =COUNTIF('FR1'!C:C, A60) -> 1 | C60: {=INDEX('FR1'!B:B, MATCH(A60, 'FR1'!C:C, 0))} -> Ritu rathi | D60: {=INDEX('FR1'!A:A, MATCH(A60, 'FR1'!C:C, 0))} -> 45300.739 | E60: {=IF(ISBLANK(INDEX('FR1'!H:H, MATCH(A60, 'FR1'!C:C, 0))), "LEAD OPEN", INDEX('FR1'!H:H, MATCH(A60, 'FR1'!C:C, 0)))} -> Gold tops
A61: 9560341110 | B61: =COUNTIF('FR1'!C:C, A61) -> 2 | C61: {=INDEX('FR1'!B:B, MATCH(A61, 'FR1'!C:C, 0))} -> Shivani | D61: {=INDEX('FR1'!A:A, MATCH(A61, 'FR1'!C:C, 0))} -> 45300.74 | E61: {=IF(ISBLANK(INDEX('FR1'!H:H, MATCH(A61, 'FR1'!C:C, 0))), "LEAD OPEN", INDEX('FR1'!H:H, MATCH(A61, 'FR1'!C:C, 0)))} -> LEAD OPEN
A62: 7021020509 | B62: =COUNTIF('FR1'!C:C, A62) -> 1 | C62: {=INDEX('FR1'!B:B, MATCH(A62, 'FR1'!C:C, 0))} -> Khushbu vijay | D62: {=INDEX('FR1'!A:A, MATCH(A62, 'FR1'!C:C, 0))} -> 45300.741 | E62: {=IF(ISBLANK(INDEX('FR1'!H:H, MATCH(A62, 'FR1'!C:C, 0))), "LEAD OPEN", INDEX('FR1'!H:H, MATCH(A62, 'FR1'!C:C, 0)))} -> LEAD OPEN
A63: 9711428669 | B63: =COUNTIF('FR1'!C:C, A63) -> 1 | C63: {=INDEX('FR1'!B:B, MATCH(A63, 'FR1'!C:C, 0))} -> Rakesh ravi | D63: {=INDEX('FR1'!A:A, MATCH(A63, 'FR1'!C:C, 0))} -> 45301.759 | E63: {=IF(ISBLANK(INDEX('FR1'!H:H, MATCH(A63, 'FR1'!C:C, 0))), "LEAD OPEN", INDEX('FR1'!H:H, MATCH(A63, 'FR1'!C:C, 0)))} -> Silver god
A64: 488017818 | B64: =COUNTIF('FR1'!C:C, A64) -> 1 | C64: {=INDEX('FR1'!B:B, MATCH(A64, 'FR1'!C:C, 0))} -> Shiba | D64: {=INDEX('FR1'!A:A, MATCH(A64, 'FR1'!C:C, 0))} -> 45301.761 | E64: {=IF(ISBLANK(INDEX('FR1'!H:H, MATCH(A64, 'FR1'!C:C, 0))), "LEAD OPEN", INDEX('FR1'!H:H, MATCH(A64, 'FR1'!C:C, 0)))} -> LEAD OPEN
A65: 9743705979 | B65: =COUNTIF('FR1'!C:C, A65) -> 1 | C65: {=INDEX('FR1'!B:B, MATCH(A65, 'FR1'!C:C, 0))} -> Manjeet | D65: {=INDEX('FR1'!A:A, MATCH(A65, 'FR1'!C:C, 0))} -> 45301.762 | E65: {=IF(ISBLANK(INDEX('FR1'!H:H, MATCH(A65, 'FR1'!C:C, 0))), "LEAD OPEN", INDEX('FR1'!H:H, MATCH(A65, 'FR1'!C:C, 0)))} -> Antic gold set, silver payal
... A67: 9810068111 | B67: =COUNTIF('FR1'!C:C, A67) -> 1 | C67: {=INDEX('FR1'!B:B, MATCH(A67, 'FR1'!C:C, 0))} -> Pc sharma | D67: {=INDEX('FR1'!A:A, MATCH(A67, 'FR1'!C:C, 0))} -> 45302.775 | E67: {=IF(ISBLANK(INDEX('FR1'!H:H, MATCH(A67, 'FR1'!C:C, 0))), "LEAD OPEN", INDEX('FR1'!H:H, MATCH(A67, 'FR1'!C:C, 0)))} -> Chain with diamond pendant
A68: 61+488017818 | B68: =COUNTIF('FR1'!C:C, A68) -> 1 | C68: {=INDEX('FR1'!B:B, MATCH(A68, 'FR1'!C:C, 0))} -> Shiba | D68: {=INDEX('FR1'!A:A, MATCH(A68, 'FR1'!C:C, 0))} -> 45302.776 | E68: {=IF(ISBLANK(INDEX('FR1'!H:H, MATCH(A68, 'FR1'!C:C, 0))), "LEAD OPEN", INDEX('FR1'!H:H, MATCH(A68, 'FR1'!C:C, 0)))} -> LEAD OPEN
A69: 9899222680 | B69: =COUNTIF('FR1'!C:C, A69) -> 1 | C69: {=INDEX('FR1'!B:B, MATCH(A69, 'FR1'!C:C, 0))} -> Sumit | D69: {=INDEX('FR1'!A:A, MATCH(A69, 'FR1'!C:C, 0))} -> 45302.777 | E69: {=IF(ISBLANK(INDEX('FR1'!H:H, MATCH(A69, 'FR1'!C:C, 0))), "LEAD OPEN", INDEX('FR1'!H:H, MATCH(A69, 'FR1'!C:C, 0)))} -> LEAD OPEN
A70: 0911019947 | B70: =COUNTIF('FR1'!C:C, A70) -> 1 | C70: {=INDEX('FR1'!B:B, MATCH(A70, 'FR1'!C:C, 0))} -> Vabhav garg | D70: {=INDEX('FR1'!A:A, MATCH(A70, 'FR1'!C:C, 0))} -> 45302.807 | E70: {=IF(ISBLANK(INDEX('FR1'!H:H, MATCH(A70, 'FR1'!C:C, 0))), "LEAD OPEN", INDEX('FR1'!H:H, MATCH(A70, 'FR1'!C:C, 0)))} -> LEAD OPEN
A71: 9711216574 | B71: =COUNTIF('FR1'!C:C, A71) -> 1 | C71: {=INDEX('FR1'!B:B, MATCH(A71, 'FR1'!C:C, 0))} -> Rajni | D71: {=INDEX('FR1'!A:A, MATCH(A71, 'FR1'!C:C, 0))} -> 45302.808 | E71: {=IF(ISBLANK(INDEX('FR1'!H:H, MATCH(A71, 'FR1'!C:C, 0))), "LEAD OPEN", INDEX('FR1'!H:H, MATCH(A71, 'FR1'!C:C, 0)))} -> LEAD OPEN
A72: 8010046101 | B72: =COUNTIF('FR1'!C:C, A72) -> 3 | C72: {=INDEX('FR1'!B:B, MATCH(A72, 'FR1'!C:C, 0))} -> Anita kapoor | D72: {=INDEX('FR1'!A:A, MATCH(A72, 'FR1'!C:C, 0))} -> 45303.772 | E72: {=IF(ISBLANK(INDEX('FR1'!H:H, MATCH(A72, 'FR1'!C:C, 0))), "LEAD OPEN", INDEX('FR1'!H:H, MATCH(A72, 'FR1'!C:C, 0)))} -> LEAD OPEN
A73: 9780560701 | B73: =COUNTIF('FR1'!C:C, A73) -> 1 | C73: {=INDEX('FR1'!B:B, MATCH(A73, 'FR1'!C:C, 0))} -> Hina | D73: {=INDEX('FR1'!A:A, MATCH(A73, 'FR1'!C:C, 0))} -> 45304.747 | E73: {=IF(ISBLANK(INDEX('FR1'!H:H, MATCH(A73, 'FR1'!C:C, 0))), "LEAD OPEN", INDEX('FR1'!H:H, MATCH(A73, 'FR1'!C:C, 0)))} -> LEAD OPEN
A74: 8700909391 | B74: =COUNTIF('FR1'!C:C, A74) -> 1 | C74: {=INDEX('FR1'!B:B, MATCH(A74, 'FR1'!C:C, 0))} -> Poonam | D74: {=INDEX('FR1'!A:A, MATCH(A74, 'FR1'!C:C, 0))} -> 45304.748 | E74: {=IF(ISBLANK(INDEX('FR1'!H:H, MATCH(A74, 'FR1'!C:C, 0))), "LEAD OPEN", INDEX('FR1'!H:H, MATCH(A74, 'FR1'!C:C, 0)))} -> Gold bali
A75: 8860036737 | B75: =COUNTIF('FR1'!C:C, A75) -> 1 | C75: {=INDEX('FR1'!B:B, MATCH(A75, 'FR1'!C:C, 0))} -> Kavita | D75: {=INDEX('FR1'!A:A, MATCH(A75, 'FR1'!C:C, 0))} -> 45304.749 | E75: {=IF(ISBLANK(INDEX('FR1'!H:H, MATCH(A75, 'FR1'!C:C, 0))), "LEAD OPEN", INDEX('FR1'!H:H, MATCH(A75, 'FR1'!C:C, 0)))} -> LEAD OPEN
A76: 7385216713 | B76: =COUNTIF('FR1'!C:C, A76) -> 1 | C76: {=INDEX('FR1'!B:B, MATCH(A76, 'FR1'!C:C, 0))} -> Umera | D76: {=INDEX('FR1'!A:A, MATCH(A76, 'FR1'!C:C, 0))} -> 45305.752 | E76: {=IF(ISBLANK(INDEX('FR1'!H:H, MATCH(A76, 'FR1'!C:C, 0))), "LEAD OPEN", INDEX('FR1'!H:H, MATCH(A76, 'FR1'!C:C, 0)))} -> LEAD OPEN
A77: 9810337136 | B77: =COUNTIF('FR1'!C:C, A77) -> 1 | C77: {=INDEX('FR1'!B:B, MATCH(A77, 'FR1'!C:C, 0))} -> Gagan | D77: {=INDEX('FR1'!A:A, MATCH(A77, 'FR1'!C:C, 0))} -> 45305.753 | E77: {=IF(ISBLANK(INDEX('FR1'!H:H, MATCH(A77, 'FR1'!C:C, 0))), "LEAD OPEN", INDEX('FR1'!H:H, MATCH(A77, 'FR1'!C:C, 0)))} -> LEAD OPEN
A78: 9899442938 | B78: =COUNTIF('FR1'!C:C, A78) -> 1 | C78: {=INDEX('FR1'!B:B, MATCH(A78, 'FR1'!C:C, 0))} -> Sanjay | D78: {=INDEX('FR1'!A:A, MATCH(A78, 'FR1'!C:C, 0))} -> 45305.754 | E78: {=IF(ISBLANK(INDEX('FR1'!H:H, MATCH(A78, 'FR1'!C:C, 0))), "LEAD OPEN", INDEX('FR1'!H:H, MATCH(A78, 'FR1'!C:C, 0)))} -> Gold chain
...
